Workbook

Sheet PL4_TONG_HOP
A1: ROW_ID | B1: MA_TIEU_CHI | C1: NOI_DUNG_TIEU_CHI | D1: CAP_TIEU_CHI | E1: CO_NHAP_LIEU | F1: Văn phòng UBND tỉnh | G1: Sở Tài chính | H1: Sở Nông nghiệp và Môi trường | I1: Sở Xây dựng | J1: Sở Tư pháp | K1: Sở Công thương | L1: Sở Văn hóa thể thao và Du lịch | M1: Sở Giáo dục và Đào tạo | N1: Sở Khoa học và Công nghệ | O1: Sở Y tế | P1: Sở Nội vụ | Q1: Sở Ngoại vụ | R1: Thanh tra tỉnh | S1: Sở Dân tộc và Tôn giáo | T1: Ban Quản lý KKTNS và Các KCN | U1: Viện quy hoạch kiến trúc Thanh Hóa
A2: R9 | B2: A | C2: A. TIÊU CHÍ ĐÁNH GIÁ VIỆC LÃNH ĐẠO, CHỈ ĐẠO, XÂY DỰNG VÀ HOÀN THIỆN CHÍNH SÁCH, PHÁP LUẬT VỀ PCTN | D2: 1 | E2: Không
A3: R10 | B3: A.1 | C3: A.1. Đánh giá việc lãnh đạo, chỉ đạo công tác PCTN: | D3: 2 | E3: Không
A4: R11 | B4: A.1.1 | C4: A.1.1. Triển khai thực hiện các văn bản của các cơ quan ở Trung ương về PCTN trong năm 2025 | D4: 3 | E4: Không
A5: R12 | B5: A.1.1.1 | C5: A.1.1.1. Triển khai thực hiện Chương trình công tác năm 2025 của Ban Chỉ đạo Trung ương về phòng, chống tham nhũng, tiêu cực. | D5: 4 | E5: Không
A6: R13 | B6: A.1.1.2 | C6: A.1.1.2. Triển khai thực hiện Nghị quyết số 168/NQ-CP ngày 11/10/2023 về Chiến lược quốc gia phòng, chống tham nhũng, tiêu cực đến năm 2030. | D6: 4 | E6: Không
A7: R14 | B7: A.1.1.3 | C7: A.1.1.3. Triển khai thực hiện Quy định số 132-QĐ/TW ngày 27/10/2023 của Bộ Chính trị về kiểm soát quyền lực và phòng, chống tham nhũng, tiêu cực trong hoạt động điều tra, truy tố, xét xử, thi hành án. | D7: 4 | E7: Không
A8: R15 | B8: A.1.1.4 | C8: A.1.1.4. Triển khai thực hiện Quy định số 131-QĐ/TW ngày 27/10/2023 của Bộ Chính trị về kiểm soát quyền lực và PCTNTC trong hoạt động kiểm tra, giám sát và thi hành kỷ luật đảng và trong hoạt động thanh tra, kiểm toán. | D8: 4 | E8: Không
A9: R16 | B9: A.1.1.5 | C9: A.1.1.5. Triển khai thực hiện Quy định số 178-QĐ/TW ngày 27/6/2024 của Bộ Chính trị về kiểm soát quyền lực, PCTNTC trong công tác xây dựng pháp luật. | D9: 4 | E9: Không
A10: R17 | B10: A.1.2 | C10: A.1.2. Ban hành kế hoạch PCTN năm 2025 | D10: 3 | E10: Có | R10: dsfds
A11: R18 | B11: A.1.3 | C11: A.1.3. Nội dung kế hoạch PCTN năm 2025 | D11: 3 | E11: Không
A12: R19 | B12: A.1.3.1 | C12: A.1.3.1. Về thực hiện các chỉ thị, nghị quyết của Trung ương về PCTN | D12: 4 | E12: Không
A13: R20 | B13: A.1.3.2 | C13: A.1.3.2. Về kiểm tra, rà soát, hệ thống hóa văn bản quy phạm pháp luật về PCTN | D13: 4 | E13: Không
A14: R21 | B14: A.1.3.3 | C14: A.1.3.3. Về xây dựng và hoàn thiện chính sách, pháp luật về PCTN | D14: 4 | E14: Không
A15: R22 | B15: A.1.3.4 | C15: A.1.3.4. Về tuyên truyền, phổ biến giáo dục pháp luật về PCTN | D15: 4 | E15: Không
A16: R23 | B16: A.1.3.5 | C16: A.1.3.5. Về kiểm tra và theo dõi thi hành văn bản quy phạm pháp luật về PCTN | D16: 4 | E16: Không
A17: R24 | B17: A.1.3.6 | C17: A.1.3.6. Về kiểm tra, đánh giá việc thực hiện kế hoạch PCTN năm 2025 | D17: 4 | E17: Không
A18: R25 | B18: A.2 | C18: A.2. Đánh giá việc UBND tỉnh và các sở, ban, cơ quan, đơn vị thuộc UBND cấp tỉnh thực hiện kế hoạch PCTN của cấp tỉnh | D18: 2 | E18: Không
A19: R26 | B19: A.2.1 | C19: A.2.1. Thực hiện kiểm tra, rà soát, hệ thống hóa văn bản quy phạm pháp luật về PCTN | D19: 3 | E19: Không
A20: R27 | B20: A.2.1.1 | C20: A.2.1.1. Ban hành kế hoạch | D20: 4 | E20: Có
A21: R28 | B21: A.2.1.2 | C21: A.2.1.2. Kết quả thực hiện | D21: 4 | E21: Có
A22: R29 | B22: A.2.3 | C22: A.2.3. Thực hiện công tác tuyên truyền, phổ biến, giáo dục pháp luật về PCTN. | D22: 3 | E22: Không
... A99: R106 | B99: ĐT.3 | C99: ĐT.3. Người đứng đầu, cấp phó của người đứng đầu cấp tỉnh bị xử lý do để xảy ra tham nhũng, tiêu cực năm 2025 | D99: 2 | E99: Có

Sheet THEO_DOI
A1: MA_DON_VI | B1: TEN_DON_VI | C1: SO_DONG_CAN_NHAP | D1: SO_DONG_DA_NHAP | E1: SO_DONG_CO_MINH_CHUNG | F1: SO_DONG_CHUA_CO_MINH_CHUNG | G1: TY_LE_DA_NHAP | H1: TY_LE_DU_MINH_CHUNG | I1: SO_FILE_DA_UPLOAD | J1: CANH_BAO | K1: DS_MA_TC_CHUA_CO_MC
A2: DV01 | B2: Văn phòng UBND tỉnh | C2: =COUNTIF(DM_TIEU_CHI!$E$2:$E$200,"Có") -> 52 | D2: =SUMPRODUCT((PL4_TONG_HOP!$E$2:$E$5000="Có")*(LEN(PL4_TONG_HOP!$F$2:$F$5000)>0)) -> 0 | E2: =SUMPRODUCT((CANH_BAO_MINH_CHUNG!$A$2:$A$5000=$A2)*(LEN(CANH_BAO_MINH_CHUNG!$F$2:$F$5000)>0)*(CANH_BAO_MINH_CHUNG!$G$2:$G$5000>0)) -> 0 | F2: =SUMPRODUCT((CANH_BAO_MINH_CHUNG!$A$2:$A$5000=$A2)*(LEN(CANH_BAO_MINH_CHUNG!$F$2:$F$5000)>0)*(CANH_BAO_MINH_CHUNG!$G$2:$G$5000=0)) -> 0 | G2: =IF(D2=0,0,D2/C2) -> 0 | H2: =IF(D2=0,0,E2/D2) -> 0 | I2: =COUNTIFS(FILE_UPLOADS!$B:$B,$A2) -> 0 | J2: =IF(D2=0,"Chưa nhập dữ liệu",IF(F2=0,"Đủ minh chứng","Thiếu minh chứng "&F2&" tiêu chí")) -> Chưa nhập dữ liệu | K2: =IF(F2=0,"","Xem sheet CANH_BAO_MINH_CHUNG")
A3: DV02 | B3: Sở Tài chính | C3: =COUNTIF(DM_TIEU_CHI!$E$2:$E$200,"Có") -> 52 | D3: =SUMPRODUCT((PL4_TONG_HOP!$E$2:$E$5000="Có")*(LEN(PL4_TONG_HOP!$G$2:$G$5000)>0)) -> 0 | E3: =SUMPRODUCT((CANH_BAO_MINH_CHUNG!$A$2:$A$5000=$A3)*(LEN(CANH_BAO_MINH_CHUNG!$F$2:$F$5000)>0)*(CANH_BAO_MINH_CHUNG!$G$2:$G$5000>0)) -> 0 | F3: =SUMPRODUCT((CANH_BAO_MINH_CHUNG!$A$2:$A$5000=$A3)*(LEN(CANH_BAO_MINH_CHUNG!$F$2:$F$5000)>0)*(CANH_BAO_MINH_CHUNG!$G$2:$G$5000=0)) -> 0 | G3: =IF(D3=0,0,D3/C3) -> 0 | H3: =IF(D3=0,0,E3/D3) -> 0 | I3: =COUNTIFS(FILE_UPLOADS!$B:$B,$A3) -> 0 | J3: =IF(D3=0,"Chưa nhập dữ liệu",IF(F3=0,"Đủ minh chứng","Thiếu minh chứng "&F3&" tiêu chí")) -> Chưa nhập dữ liệu | K3: =IF(F3=0,"","Xem sheet CANH_BAO_MINH_CHUNG")
A4: DV03 | B4: Sở Nông nghiệp và Môi trường | C4: =COUNTIF(DM_TIEU_CHI!$E$2:$E$200,"Có") -> 52 | D4: =SUMPRODUCT((PL4_TONG_HOP!$E$2:$E$5000="Có")*(LEN(PL4_TONG_HOP!$H$2:$H$5000)>0)) -> 0 | E4: =SUMPRODUCT((CANH_BAO_MINH_CHUNG!$A$2:$A$5000=$A4)*(LEN(CANH_BAO_MINH_CHUNG!$F$2:$F$5000)>0)*(CANH_BAO_MINH_CHUNG!$G$2:$G$5000>0)) -> 0 | F4: =SUMPRODUCT((CANH_BAO_MINH_CHUNG!$A$2:$A$5000=$A4)*(LEN(CANH_BAO_MINH_CHUNG!$F$2:$F$5000)>0)*(CANH_BAO_MINH_CHUNG!$G$2:$G$5000=0)) -> 0 | G4: =IF(D4=0,0,D4/C4) -> 0 | H4: =IF(D4=0,0,E4/D4) -> 0 | I4: =COUNTIFS(FILE_UPLOADS!$B:$B,$A4) -> 0 | J4: =IF(D4=0,"Chưa nhập dữ liệu",IF(F4=0,"Đủ minh chứng","Thiếu minh chứng "&F4&" tiêu chí")) -> Chưa nhập dữ liệu | K4: =IF(F4=0,"","Xem sheet CANH_BAO_MINH_CHUNG")
A5: DV04 | B5: Sở Xây dựng | C5: =COUNTIF(DM_TIEU_CHI!$E$2:$E$200,"Có") -> 52 | D5: =SUMPRODUCT((PL4_TONG_HOP!$E$2:$E$5000="Có")*(LEN(PL4_TONG_HOP!$I$2:$I$5000)>0)) -> 0 | E5: =SUMPRODUCT((CANH_BAO_MINH_CHUNG!$A$2:$A$5000=$A5)*(LEN(CANH_BAO_MINH_CHUNG!$F$2:$F$5000)>0)*(CANH_BAO_MINH_CHUNG!$G$2:$G$5000>0)) -> 0 | F5: =SUMPRODUCT((CANH_BAO_MINH_CHUNG!$A$2:$A$5000=$A5)*(LEN(CANH_BAO_MINH_CHUNG!$F$2:$F$5000)>0)*(CANH_BAO_MINH_CHUNG!$G$2:$G$5000=0)) -> 0 | G5: =IF(D5=0,0,D5/C5) -> 0 | H5: =IF(D5=0,0,E5/D5) -> 0 | I5: =COUNTIFS(FILE_UPLOADS!$B:$B,$A5) -> 0 | J5: =IF(D5=0,"Chưa nhập dữ liệu",IF(F5=0,"Đủ minh chứng","Thiếu minh chứng "&F5&" tiêu chí")) -> Chưa nhập dữ liệu | K5: =IF(F5=0,"","Xem sheet CANH_BAO_MINH_CHUNG")
A6: DV05 | B6: Sở Tư pháp | C6: =COUNTIF(DM_TIEU_CHI!$E$2:$E$200,"Có") -> 52 | D6: =SUMPRODUCT((PL4_TONG_HOP!$E$2:$E$5000="Có")*(LEN(PL4_TONG_HOP!$J$2:$J$5000)>0)) -> 0 | E6: =SUMPRODUCT((CANH_BAO_MINH_CHUNG!$A$2:$A$5000=$A6)*(LEN(CANH_BAO_MINH_CHUNG!$F$2:$F$5000)>0)*(CANH_BAO_MINH_CHUNG!$G$2:$G$5000>0)) -> 0 | F6: =SUMPRODUCT((CANH_BAO_MINH_CHUNG!$A$2:$A$5000=$A6)*(LEN(CANH_BAO_MINH_CHUNG!$F$2:$F$5000)>0)*(CANH_BAO_MINH_CHUNG!$G$2:$G$5000=0)) -> 0 | G6: =IF(D6=0,0,D6/C6) -> 0 | H6: =IF(D6=0,0,E6/D6) -> 0 | I6: =COUNTIFS(FILE_UPLOADS!$B:$B,$A6) -> 0 | J6: =IF(D6=0,"Chưa nhập dữ liệu",IF(F6=0,"Đủ minh chứng","Thiếu minh chứng "&F6&" tiêu chí")) -> Chưa nhập dữ liệu | K6: =IF(F6=0,"","Xem sheet CANH_BAO_MINH_CHUNG")
A7: DV06 | B7: Sở Công thương | C7: =COUNTIF(DM_TIEU_CHI!$E$2:$E$200,"Có") -> 52 | D7: =SUMPRODUCT((PL4_TONG_HOP!$E$2:$E$5000="Có")*(LEN(PL4_TONG_HOP!$K$2:$K$5000)>0)) -> 0 | E7: =SUMPRODUCT((CANH_BAO_MINH_CHUNG!$A$2:$A$5000=$A7)*(LEN(CANH_BAO_MINH_CHUNG!$F$2:$F$5000)>0)*(CANH_BAO_MINH_CHUNG!$G$2:$G$5000>0)) -> 0 | F7: =SUMPRODUCT((CANH_BAO_MINH_CHUNG!$A$2:$A$5000=$A7)*(LEN(CANH_BAO_MINH_CHUNG!$F$2:$F$5000)>0)*(CANH_BAO_MINH_CHUNG!$G$2:$G$5000=0)) -> 0 | G7: =IF(D7=0,0,D7/C7) -> 0 | H7: =IF(D7=0,0,E7/D7) -> 0 | I7: =COUNTIFS(FILE_UPLOADS!$B:$B,$A7) -> 0 | J7: =IF(D7=0,"Chưa nhập dữ liệu",IF(F7=0,"Đủ minh chứng","Thiếu minh chứng "&F7&" tiêu chí")) -> Chưa nhập dữ liệu | K7: =IF(F7=0,"","Xem sheet CANH_BAO_MINH_CHUNG")
A8: DV07 | B8: Sở Văn hóa thể thao và Du lịch | C8: =COUNTIF(DM_TIEU_CHI!$E$2:$E$200,"Có") -> 52 | D8: =SUMPRODUCT((PL4_TONG_HOP!$E$2:$E$5000="Có")*(LEN(PL4_TONG_HOP!$L$2:$L$5000)>0)) -> 0 | E8: =SUMPRODUCT((CANH_BAO_MINH_CHUNG!$A$2:$A$5000=$A8)*(LEN(CANH_BAO_MINH_CHUNG!$F$2:$F$5000)>0)*(CANH_BAO_MINH_CHUNG!$G$2:$G$5000>0)) -> 0 | F8: =SUMPRODUCT((CANH_BAO_MINH_CHUNG!$A$2:$A$5000=$A8)*(LEN(CANH_BAO_MINH_CHUNG!$F$2:$F$5000)>0)*(CANH_BAO_MINH_CHUNG!$G$2:$G$5000=0)) -> 0 | G8: =IF(D8=0,0,D8/C8) -> 0 | H8: =IF(D8=0,0,E8/D8) -> 0 | I8: =COUNTIFS(FILE_UPLOADS!$B:$B,$A8) -> 0 | J8: =IF(D8=0,"Chưa nhập dữ liệu",IF(F8=0,"Đủ minh chứng","Thiếu minh chứng "&F8&" tiêu chí")) -> Chưa nhập dữ liệu | K8: =IF(F8=0,"","Xem sheet CANH_BAO_MINH_CHUNG")
A9: DV08 | B9: Sở Giáo dục và Đào tạo | C9: =COUNTIF(DM_TIEU_CHI!$E$2:$E$200,"Có") -> 52 | D9: =SUMPRODUCT((PL4_TONG_HOP!$E$2:$E$5000="Có")*(LEN(PL4_TONG_HOP!$M$2:$M$5000)>0)) -> 0 | E9: =SUMPRODUCT((CANH_BAO_MINH_CHUNG!$A$2:$A$5000=$A9)*(LEN(CANH_BAO_MINH_CHUNG!$F$2:$F$5000)>0)*(CANH_BAO_MINH_CHUNG!$G$2:$G$5000>0)) -> 0 | F9: =SUMPRODUCT((CANH_BAO_MINH_CHUNG!$A$2:$A$5000=$A9)*(LEN(CANH_BAO_MINH_CHUNG!$F$2:$F$5000)>0)*(CANH_BAO_MINH_CHUNG!$G$2:$G$5000=0)) -> 0 | G9: =IF(D9=0,0,D9/C9) -> 0 | H9: =IF(D9=0,0,E9/D9) -> 0 | I9: =COUNTIFS(FILE_UPLOADS!$B:$B,$A9) -> 0 | J9: =IF(D9=0,"Chưa nhập dữ liệu",IF(F9=0,"Đủ minh chứng","Thiếu minh chứng "&F9&" tiêu chí")) -> Chưa nhập dữ liệu | K9: =IF(F9=0,"","Xem sheet CANH_BAO_MINH_CHUNG")
A10: DV09 | B10: Sở Khoa học và Công nghệ | C10: =COUNTIF(DM_TIEU_CHI!$E$2:$E$200,"Có") -> 52 | D10: =SUMPRODUCT((PL4_TONG_HOP!$E$2:$E$5000="Có")*(LEN(PL4_TONG_HOP!$N$2:$N$5000)>0)) -> 0 | E10: =SUMPRODUCT((CANH_BAO_MINH_CHUNG!$A$2:$A$5000=$A10)*(LEN(CANH_BAO_MINH_CHUNG!$F$2:$F$5000)>0)*(CANH_BAO_MINH_CHUNG!$G$2:$G$5000>0)) -> 0 | F10: =SUMPRODUCT((CANH_BAO_MINH_CHUNG!$A$2:$A$5000=$A10)*(LEN(CANH_BAO_MINH_CHUNG!$F$2:$F$5000)>0)*(CANH_BAO_MINH_CHUNG!$G$2:$G$5000=0)) -> 0 | G10: =IF(D10=0,0,D10/C10) -> 0 | H10: =IF(D10=0,0,E10/D10) -> 0 | I10: =COUNTIFS(FILE_UPLOADS!$B:$B,$A10) -> 0 | J10: =IF(D10=0,"Chưa nhập dữ liệu",IF(F10=0,"Đủ minh chứng","Thiếu minh chứng "&F10&" tiêu chí")) -> Chưa nhập dữ liệu | K10: =IF(F10=0,"","Xem sheet CANH_BAO_MINH_CHUNG")
A11: DV10 | B11: Sở Y tế | C11: =COUNTIF(DM_TIEU_CHI!$E$2:$E$200,"Có") -> 52 | D11: =SUMPRODUCT((PL4_TONG_HOP!$E$2:$E$5000="Có")*(LEN(PL4_TONG_HOP!$O$2:$O$5000)>0)) -> 0 | E11: =SUMPRODUCT((CANH_BAO_MINH_CHUNG!$A$2:$A$5000=$A11)*(LEN(CANH_BAO_MINH_CHUNG!$F$2:$F$5000)>0)*(CANH_BAO_MINH_CHUNG!$G$2:$G$5000>0)) -> 0 | F11: =SUMPRODUCT((CANH_BAO_MINH_CHUNG!$A$2:$A$5000=$A11)*(LEN(CANH_BAO_MINH_CHUNG!$F$2:$F$5000)>0)*(CANH_BAO_MINH_CHUNG!$G$2:$G$5000=0)) -> 0 | G11: =IF(D11=0,0,D11/C11) -> 0 | H11: =IF(D11=0,0,E11/D11) -> 0 | I11: =COUNTIFS(FILE_UPLOADS!$B:$B,$A11) -> 0 | J11: =IF(D11=0,"Chưa nhập dữ liệu",IF(F11=0,"Đủ minh chứng","Thiếu minh chứng "&F11&" tiêu chí")) -> Chưa nhập dữ liệu | K11: =IF(F11=0,"","Xem sheet CANH_BAO_MINH_CHUNG")
A12: DV11 | B12: Sở Nội vụ | C12: =COUNTIF(DM_TIEU_CHI!$E$2:$E$200,"Có") -> 52 | D12: =SUMPRODUCT((PL4_TONG_HOP!$E$2:$E$5000="Có")*(LEN(PL4_TONG_HOP!$P$2:$P$5000)>0)) -> 0 | E12: =SUMPRODUCT((CANH_BAO_MINH_CHUNG!$A$2:$A$5000=$A12)*(LEN(CANH_BAO_MINH_CHUNG!$F$2:$F$5000)>0)*(CANH_BAO_MINH_CHUNG!$G$2:$G$5000>0)) -> 0 | F12: =SUMPRODUCT((CANH_BAO_MINH_CHUNG!$A$2:$A$5000=$A12)*(LEN(CANH_BAO_MINH_CHUNG!$F$2:$F$5000)>0)*(CANH_BAO_MINH_CHUNG!$G$2:$G$5000=0)) -> 0 | G12: =IF(D12=0,0,D12/C12) -> 0 | H12: =IF(D12=0,0,E12/D12) -> 0 | I12: =COUNTIFS(FILE_UPLOADS!$B:$B,$A12) -> 0 | J12: =IF(D12=0,"Chưa nhập dữ liệu",IF(F12=0,"Đủ minh chứng","Thiếu minh chứng "&F12&" tiêu chí")) -> Chưa nhập dữ liệu | K12: =IF(F12=0,"","Xem sheet CANH_BAO_MINH_CHUNG")
A13: DV12 | B13: Sở Ngoại vụ | C13: =COUNTIF(DM_TIEU_CHI!$E$2:$E$200,"Có") -> 52 | D13: =SUMPRODUCT((PL4_TONG_HOP!$E$2:$E$5000="Có")*(LEN(PL4_TONG_HOP!$Q$2:$Q$5000)>0)) -> 0 | E13: =SUMPRODUCT((CANH_BAO_MINH_CHUNG!$A$2:$A$5000=$A13)*(LEN(CANH_BAO_MINH_CHUNG!$F$2:$F$5000)>0)*(CANH_BAO_MINH_CHUNG!$G$2:$G$5000>0)) -> 0 | F13: =SUMPRODUCT((CANH_BAO_MINH_CHUNG!$A$2:$A$5000=$A13)*(LEN(CANH_BAO_MINH_CHUNG!$F$2:$F$5000)>0)*(CANH_BAO_MINH_CHUNG!$G$2:$G$5000=0)) -> 0 | G13: =IF(D13=0,0,D13/C13) -> 0 | H13: =IF(D13=0,0,E13/D13) -> 0 | I13: =COUNTIFS(FILE_UPLOADS!$B:$B,$A13) -> 0 | J13: =IF(D13=0,"Chưa nhập dữ liệu",IF(F13=0,"Đủ minh chứng","Thiếu minh chứng "&F13&" tiêu chí")) -> Chưa nhập dữ liệu | K13: =IF(F13=0,"","Xem sheet CANH_BAO_MINH_CHUNG")
A14: DV13 | B14: Thanh tra tỉnh | C14: =COUNTIF(DM_TIEU_CHI!$E$2:$E$200,"Có") -> 52 | D14: =SUMPRODUCT((PL4_TONG_HOP!$E$2:$E$5000="Có")*(LEN(PL4_TONG_HOP!$R$2:$R$5000)>0)) -> 1 | E14: =SUMPRODUCT((CANH_BAO_MINH_CHUNG!$A$2:$A$5000=$A14)*(LEN(CANH_BAO_MINH_CHUNG!$F$2:$F$5000)>0)*(CANH_BAO_MINH_CHUNG!$G$2:$G$5000>0)) -> 1 | F14: =SUMPRODUCT((CANH_BAO_MINH_CHUNG!$A$2:$A$5000=$A14)*(LEN(CANH_BAO_MINH_CHUNG!$F$2:$F$5000)>0)*(CANH_BAO_MINH_CHUNG!$G$2:$G$5000=0)) -> 0 | G14: =IF(D14=0,0,D14/C14) -> 0.019230769 | H14: =IF(D14=0,0,E14/D14) -> 1 | I14: =COUNTIFS(FILE_UPLOADS!$B:$B,$A14) -> 1 | J14: =IF(D14=0,"Chưa nhập dữ liệu",IF(F14=0,"Đủ minh chứng","Thiếu minh chứng "&F14&" tiêu chí")) -> Đủ minh chứng | K14: =IF(F14=0,"","Xem sheet CANH_BAO_MINH_CHUNG")
A15: DV14 | B15: Sở Dân tộc và Tôn giáo | C15: =COUNTIF(DM_TIEU_CHI!$E$2:$E$200,"Có") -> 52 | D15: =SUMPRODUCT((PL4_TONG_HOP!$E$2:$E$5000="Có")*(LEN(PL4_TONG_HOP!$S$2:$S$5000)>0)) -> 0 | E15: =SUMPRODUCT((CANH_BAO_MINH_CHUNG!$A$2:$A$5000=$A15)*(LEN(CANH_BAO_MINH_CHUNG!$F$2:$F$5000)>0)*(CANH_BAO_MINH_CHUNG!$G$2:$G$5000>0)) -> 0 | F15: =SUMPRODUCT((CANH_BAO_MINH_CHUNG!$A$2:$A$5000=$A15)*(LEN(CANH_BAO_MINH_CHUNG!$F$2:$F$5000)>0)*(CANH_BAO_MINH_CHUNG!$G$2:$G$5000=0)) -> 0 | G15: =IF(D15=0,0,D15/C15) -> 0 | H15: =IF(D15=0,0,E15/D15) -> 0 | I15: =COUNTIFS(FILE_UPLOADS!$B:$B,$A15) -> 0 | J15: =IF(D15=0,"Chưa nhập dữ liệu",IF(F15=0,"Đủ minh chứng","Thiếu minh chứng "&F15&" tiêu chí")) -> Chưa nhập dữ liệu | K15: =IF(F15=0,"","Xem sheet CANH_BAO_MINH_CHUNG")
A16: DV15 | B16: Ban Quản lý KKTNS và Các KCN | C16: =COUNTIF(DM_TIEU_CHI!$E$2:$E$200,"Có") -> 52 | D16: =SUMPRODUCT((PL4_TONG_HOP!$E$2:$E$5000="Có")*(LEN(PL4_TONG_HOP!$T$2:$T$5000)>0)) -> 0 | E16: =SUMPRODUCT((CANH_BAO_MINH_CHUNG!$A$2:$A$5000=$A16)*(LEN(CANH_BAO_MINH_CHUNG!$F$2:$F$5000)>0)*(CANH_BAO_MINH_CHUNG!$G$2:$G$5000>0)) -> 0 | F16: =SUMPRODUCT((CANH_BAO_MINH_CHUNG!$A$2:$A$5000=$A16)*(LEN(CANH_BAO_MINH_CHUNG!$F$2:$F$5000)>0)*(CANH_BAO_MINH_CHUNG!$G$2:$G$5000=0)) -> 0 | G16: =IF(D16=0,0,D16/C16) -> 0 | H16: =IF(D16=0,0,E16/D16) -> 0 | I16: =COUNTIFS(FILE_UPLOADS!$B:$B,$A16) -> 0 | J16: =IF(D16=0,"Chưa nhập dữ liệu",IF(F16=0,"Đủ minh chứng","Thiếu minh chứng "&F16&" tiêu chí")) -> Chưa nhập dữ liệu | K16: =IF(F16=0,"","Xem sheet CANH_BAO_MINH_CHUNG")
A17: DV16 | B17: Viện quy hoạch kiến trúc Thanh Hóa | C17: =COUNTIF(DM_TIEU_CHI!$E$2:$E$200,"Có") -> 52 | D17: =SUMPRODUCT((PL4_TONG_HOP!$E$2:$E$5000="Có")*(LEN(PL4_TONG_HOP!$U$2:$U$5000)>0)) -> 0 | E17: =SUMPRODUCT((CANH_BAO_MINH_CHUNG!$A$2:$A$5000=$A17)*(LEN(CANH_BAO_MINH_CHUNG!$F$2:$F$5000)>0)*(CANH_BAO_MINH_CHUNG!$G$2:$G$5000>0)) -> 0 | F17: =SUMPRODUCT((CANH_BAO_MINH_CHUNG!$A$2:$A$5000=$A17)*(LEN(CANH_BAO_MINH_CHUNG!$F$2:$F$5000)>0)*(CANH_BAO_MINH_CHUNG!$G$2:$G$5000=0)) -> 0 | G17: =IF(D17=0,0,D17/C17) -> 0 | H17: =IF(D17=0,0,E17/D17) -> 0 | I17: =COUNTIFS(FILE_UPLOADS!$B:$B,$A17) -> 0 | J17: =IF(D17=0,"Chưa nhập dữ liệu",IF(F17=0,"Đủ minh chứng","Thiếu minh chứng "&F17&" tiêu chí")) -> Chưa nhập dữ liệu | K17: =IF(F17=0,"","Xem sheet CANH_BAO_MINH_CHUNG")

Sheet CANH_BAO_MINH_CHUNG
A1: MA_DON_VI | B1: TEN_DON_VI | C1: ROW_ID | D1: MA_TIEU_CHI | E1: TEN_TIEU_CHI | F1: NOI_DUNG_DA_NHAP | G1: SO_FILE_UPLOAD | H1: CANH_BAO
A2: DV01 | B2: Văn phòng UBND tỉnh | C2: R17 | D2: A.1.2 | E2: A.1.2. Ban hành kế hoạch PCTN năm 2025 | F2: {=IFERROR(INDEX(PL4_TONG_HOP!$F$2:$F$5000,MATCH($C2,PL4_TONG_HOP!$A$2:$A$5000,0)),"")} | G2: =COUNTIFS(FILE_UPLOADS!$B:$B,$A2,FILE_UPLOADS!$D:$D,$C2) -> 0 | H2: =IF(LEN(F2)=0,"",IF(G2>0,"Đã có minh chứng","CHƯA CÓ MINH CHỨNG"))
A3: DV01 | B3: Văn phòng UBND tỉnh | C3: R27 | D3: A.2.1.1 | E3: A.2.1.1. Ban hành kế hoạch | F3: {=IFERROR(INDEX(PL4_TONG_HOP!$F$2:$F$5000,MATCH($C3,PL4_TONG_HOP!$A$2:$A$5000,0)),"")} | G3: =COUNTIFS(FILE_UPLOADS!$B:$B,$A3,FILE_UPLOADS!$D:$D,$C3) -> 0 | H3: =IF(LEN(F3)=0,"",IF(G3>0,"Đã có minh chứng","CHƯA CÓ MINH CHỨNG"))
A4: DV01 | B4: Văn phòng UBND tỉnh | C4: R28 | D4: A.2.1.2 | E4: A.2.1.2. Kết quả thực hiện | F4: {=IFERROR(INDEX(PL4_TONG_HOP!$F$2:$F$5000,MATCH($C4,PL4_TONG_HOP!$A$2:$A$5000,0)),"")} | G4: =COUNTIFS(FILE_UPLOADS!$B:$B,$A4,FILE_UPLOADS!$D:$D,$C4) -> 0 | H4: =IF(LEN(F4)=0,"",IF(G4>0,"Đã có minh chứng","CHƯA CÓ MINH CHỨNG"))
A5: DV01 | B5: Văn phòng UBND tỉnh | C5: R30 | D5: A.2.2.1 | E5: A.2.2.1. Ban hành kế hoạch | F5: {=IFERROR(INDEX(PL4_TONG_HOP!$F$2:$F$5000,MATCH($C5,PL4_TONG_HOP!$A$2:$A$5000,0)),"")} | G5: =COUNTIFS(FILE_UPLOADS!$B:$B,$A5,FILE_UPLOADS!$D:$D,$C5) -> 0 | H5: =IF(LEN(F5)=0,"",IF(G5>0,"Đã có minh chứng","CHƯA CÓ MINH CHỨNG"))
A6: DV01 | B6: Văn phòng UBND tỉnh | C6: R31 | D6: A.2.2.2 | E6: A.2.2.2. Kết quả thực hiện | F6: {=IFERROR(INDEX(PL4_TONG_HOP!$F$2:$F$5000,MATCH($C6,PL4_TONG_HOP!$A$2:$A$5000,0)),"")} | G6: =COUNTIFS(FILE_UPLOADS!$B:$B,$A6,FILE_UPLOADS!$D:$D,$C6) -> 0 | H6: =IF(LEN(F6)=0,"",IF(G6>0,"Đã có minh chứng","CHƯA CÓ MINH CHỨNG"))
A7: DV01 | B7: Văn phòng UBND tỉnh | C7: R32 | D7: A.2.3 | E7: A.2.3. Thực hiện việc kiểm tra và theo dõi thi hành văn bản quy phạm pháp luật về PCTN | F7: {=IFERROR(INDEX(PL4_TONG_HOP!$F$2:$F$5000,MATCH($C7,PL4_TONG_HOP!$A$2:$A$5000,0)),"")} | G7: =COUNTIFS(FILE_UPLOADS!$B:$B,$A7,FILE_UPLOADS!$D:$D,$C7) -> 0 | H7: =IF(LEN(F7)=0,"",IF(G7>0,"Đã có minh chứng","CHƯA CÓ MINH CHỨNG"))
A8: DV01 | B8: Văn phòng UBND tỉnh | C8: R33 | D8: A.2.4 | E8: A.2.4. Tiếp công dân theo quy định của Luật tiếp công dân của Chủ tịch UBND cấp tỉnh | F8: {=IFERROR(INDEX(PL4_TONG_HOP!$F$2:$F$5000,MATCH($C8,PL4_TONG_HOP!$A$2:$A$5000,0)),"")} | G8: =COUNTIFS(FILE_UPLOADS!$B:$B,$A8,FILE_UPLOADS!$D:$D,$C8) -> 0 | H8: =IF(LEN(F8)=0,"",IF(G8>0,"Đã có minh chứng","CHƯA CÓ MINH CHỨNG"))
A9: DV01 | B9: Văn phòng UBND tỉnh | C9: R34 | D9: A.2.5 | E9: A.2.5. Tiếp công dân theo quy định của Luật tiếp công dân của Người đứng đầu cơ quan chuyên môn thuộc UBND cấp Tỉnh | F9: {=IFERROR(INDEX(PL4_TONG_HOP!$F$2:$F$5000,MATCH($C9,PL4_TONG_HOP!$A$2:$A$5000,0)),"")} | G9: =COUNTIFS(FILE_UPLOADS!$B:$B,$A9,FILE_UPLOADS!$D:$D,$C9) -> 0 | H9: =IF(LEN(F9)=0,"",IF(G9>0,"Đã có minh chứng","CHƯA CÓ MINH CHỨNG"))
A10: DV01 | B10: Văn phòng UBND tỉnh | C10: R35 | D10: A.2.6 | E10: A.2.6. Việc chỉ đạo của Chủ tịch UBND cấp tỉnh xử lý tố cáo, kiến nghị, phản ánh của công dân về tham nhũng. | F10: {=IFERROR(INDEX(PL4_TONG_HOP!$F$2:$F$5000,MATCH($C10,PL4_TONG_HOP!$A$2:$A$5000,0)),"")} | G10: =COUNTIFS(FILE_UPLOADS!$B:$B,$A10,FILE_UPLOADS!$D:$D,$C10) -> 0 | H10: =IF(LEN(F10)=0,"",IF(G10>0,"Đã có minh chứng","CHƯA CÓ MINH CHỨNG"))
A11: DV01 | B11: Văn phòng UBND tỉnh | C11: R39 | D11: B.1.1.1 | E11: B.1.1.1. Kết quả thực hiện công khai, minh bạch các thủ tục hành chính | F11: {=IFERROR(INDEX(PL4_TONG_HOP!$F$2:$F$5000,MATCH($C11,PL4_TONG_HOP!$A$2:$A$5000,0)),"")} | G11: =COUNTIFS(FILE_UPLOADS!$B:$B,$A11,FILE_UPLOADS!$D:$D,$C11) -> 0 | H11: =IF(LEN(F11)=0,"",IF(G11>0,"Đã có minh chứng","CHƯA CÓ MINH CHỨNG"))
A12: DV01 | B12: Văn phòng UBND tỉnh | C12: R40 | D12: B.1.1.2 | E12: B.1.1.2. Kết quả thực hiện công khai, minh bạch quy tắc ứng xử của người có chức vụ quyền hạn | F12: {=IFERROR(INDEX(PL4_TONG_HOP!$F$2:$F$5000,MATCH($C12,PL4_TONG_HOP!$A$2:$A$5000,0)),"")} | G12: =COUNTIFS(FILE_UPLOADS!$B:$B,$A12,FILE_UPLOADS!$D:$D,$C12) -> 0 | H12: =IF(LEN(F12)=0,"",IF(G12>0,"Đã có minh chứng","CHƯA CÓ MINH CHỨNG"))
A13: DV01 | B13: Văn phòng UBND tỉnh | C13: R41 | D13: B.1.1.3 | E13: B.1.1.3. Kết quả thực hiện công khai, minh bạch tuyển dụng, bổ nhiệm công chức, viên chức | F13: {=IFERROR(INDEX(PL4_TONG_HOP!$F$2:$F$5000,MATCH($C13,PL4_TONG_HOP!$A$2:$A$5000,0)),"")} | G13: =COUNTIFS(FILE_UPLOADS!$B:$B,$A13,FILE_UPLOADS!$D:$D,$C13) -> 0 | H13: =IF(LEN(F13)=0,"",IF(G13>0,"Đã có minh chứng","CHƯA CÓ MINH CHỨNG"))
... A53: DV01 | B53: Văn phòng UBND tỉnh | C53: R106 | D53: ĐT.3 | E53: ĐT.3. Người đứng đầu, cấp phó của người đứng đầu cấp tỉnh bị xử lý do để xảy ra tham nhũng, tiêu cực năm 2025 | F53: {=IFERROR(INDEX(PL4_TONG_HOP!$F$2:$F$5000,MATCH($C53,PL4_TONG_HOP!$A$2:$A$5000,0)),"")} | G53: =COUNTIFS(FILE_UPLOADS!$B:$B,$A53,FILE_UPLOADS!$D:$D,$C53) -> 0 | H53: =IF(LEN(F53)=0,"",IF(G53>0,"Đã có minh chứng","CHƯA CÓ MINH CHỨNG"))
A54: DV02 | B54: Sở Tài chính | C54: R17 | D54: A.1.2 | E54: A.1.2. Ban hành kế hoạch PCTN năm 2025 | F54: {=IFERROR(INDEX(PL4_TONG_HOP!$G$2:$G$5000,MATCH($C54,PL4_TONG_HOP!$A$2:$A$5000,0)),"")} | G54: =COUNTIFS(FILE_UPLOADS!$B:$B,$A54,FILE_UPLOADS!$D:$D,$C54) -> 0 | H54: =IF(LEN(F54)=0,"",IF(G54>0,"Đã có minh chứng","CHƯA CÓ MINH CHỨNG"))
A55: DV02 | B55: Sở Tài chính | C55: R27 | D55: A.2.1.1 | E55: A.2.1.1. Ban hành kế hoạch | F55: {=IFERROR(INDEX(PL4_TONG_HOP!$G$2:$G$5000,MATCH($C55,PL4_TONG_HOP!$A$2:$A$5000,0)),"")} | G55: =COUNTIFS(FILE_UPLOADS!$B:$B,$A55,FILE_UPLOADS!$D:$D,$C55) -> 0 | H55: =IF(LEN(F55)=0,"",IF(G55>0,"Đã có minh chứng","CHƯA CÓ MINH CHỨNG"))
A56: DV02 | B56: Sở Tài chính | C56: R28 | D56: A.2.1.2 | E56: A.2.1.2. Kết quả thực hiện | F56: {=IFERROR(INDEX(PL4_TONG_HOP!$G$2:$G$5000,MATCH($C56,PL4_TONG_HOP!$A$2:$A$5000,0)),"")} | G56: =COUNTIFS(FILE_UPLOADS!$B:$B,$A56,FILE_UPLOADS!$D:$D,$C56) -> 0 | H56: =IF(LEN(F56)=0,"",IF(G56>0,"Đã có minh chứng","CHƯA CÓ MINH CHỨNG"))
A57: DV02 | B57: Sở Tài chính | C57: R30 | D57: A.2.2.1 | E57: A.2.2.1. Ban hành kế hoạch | F57: {=IFERROR(INDEX(PL4_TONG_HOP!$G$2:$G$5000,MATCH($C57,PL4_TONG_HOP!$A$2:$A$5000,0)),"")} | G57: =COUNTIFS(FILE_UPLOADS!$B:$B,$A57,FILE_UPLOADS!$D:$D,$C57) -> 0 | H57: =IF(LEN(F57)=0,"",IF(G57>0,"Đã có minh chứng","CHƯA CÓ MINH CHỨNG"))
A58: DV02 | B58: Sở Tài chính | C58: R31 | D58: A.2.2.2 | E58: A.2.2.2. Kết quả thực hiện | F58: {=IFERROR(INDEX(PL4_TONG_HOP!$G$2:$G$5000,MATCH($C58,PL4_TONG_HOP!$A$2:$A$5000,0)),"")} | G58: =COUNTIFS(FILE_UPLOADS!$B:$B,$A58,FILE_UPLOADS!$D:$D,$C58) -> 0 | H58: =IF(LEN(F58)=0,"",IF(G58>0,"Đã có minh chứng","CHƯA CÓ MINH CHỨNG"))
A59: DV02 | B59: Sở Tài chính | C59: R32 | D59: A.2.3 | E59: A.2.3. Thực hiện việc kiểm tra và theo dõi thi hành văn bản quy phạm pháp luật về PCTN | F59: {=IFERROR(INDEX(PL4_TONG_HOP!$G$2:$G$5000,MATCH($C59,PL4_TONG_HOP!$A$2:$A$5000,0)),"")} | G59: =COUNTIFS(FILE_UPLOADS!$B:$B,$A59,FILE_UPLOADS!$D:$D,$C59) -> 0 | H59: =IF(LEN(F59)=0,"",IF(G59>0,"Đã có minh chứng","CHƯA CÓ MINH CHỨNG"))
A60: DV02 | B60: Sở Tài chính | C60: R33 | D60: A.2.4 | E60: A.2.4. Tiếp công dân theo quy định của Luật tiếp công dân của Chủ tịch UBND cấp tỉnh | F60: {=IFERROR(INDEX(PL4_TONG_HOP!$G$2:$G$5000,MATCH($C60,PL4_TONG_HOP!$A$2:$A$5000,0)),"")} | G60: =COUNTIFS(FILE_UPLOADS!$B:$B,$A60,FILE_UPLOADS!$D:$D,$C60) -> 0 | H60: =IF(LEN(F60)=0,"",IF(G60>0,"Đã có minh chứng","CHƯA CÓ MINH CHỨNG"))
A61: DV02 | B61: Sở Tài chính | C61: R34 | D61: A.2.5 | E61: A.2.5. Tiếp công dân theo quy định của Luật tiếp công dân của Người đứng đầu cơ quan chuyên môn thuộc UBND cấp Tỉnh | F61: {=IFERROR(INDEX(PL4_TONG_HOP!$G$2:$G$5000,MATCH($C61,PL4_TONG_HOP!$A$2:$A$5000,0)),"")} | G61: =COUNTIFS(FILE_UPLOADS!$B:$B,$A61,FILE_UPLOADS!$D:$D,$C61) -> 0 | H61: =IF(LEN(F61)=0,"",IF(G61>0,"Đã có minh chứng","CHƯA CÓ MINH CHỨNG"))
A62: DV02 | B62: Sở Tài chính | C62: R35 | D62: A.2.6 | E62: A.2.6. Việc chỉ đạo của Chủ tịch UBND cấp tỉnh xử lý tố cáo, kiến nghị, phản ánh của công dân về tham nhũng. | F62: {=IFERROR(INDEX(PL4_TONG_HOP!$G$2:$G$5000,MATCH($C62,PL4_TONG_HOP!$A$2:$A$5000,0)),"")} | G62: =COUNTIFS(FILE_UPLOADS!$B:$B,$A62,FILE_UPLOADS!$D:$D,$C62) -> 0 | H62: =IF(LEN(F62)=0,"",IF(G62>0,"Đã có minh chứng","CHƯA CÓ MINH CHỨNG"))
A63: DV02 | B63: Sở Tài chính | C63: R39 | D63: B.1.1.1 | E63: B.1.1.1. Kết quả thực hiện công khai, minh bạch các thủ tục hành chính | F63: {=IFERROR(INDEX(PL4_TONG_HOP!$G$2:$G$5000,MATCH($C63,PL4_TONG_HOP!$A$2:$A$5000,0)),"")} | G63: =COUNTIFS(FILE_UPLOADS!$B:$B,$A63,FILE_UPLOADS!$D:$D,$C63) -> 0 | H63: =IF(LEN(F63)=0,"",IF(G63>0,"Đã có minh chứng","CHƯA CÓ MINH CHỨNG"))
A64: DV02 | B64: Sở Tài chính | C64: R40 | D64: B.1.1.2 | E64: B.1.1.2. Kết quả thực hiện công khai, minh bạch quy tắc ứng xử của người có chức vụ quyền hạn | F64: {=IFERROR(INDEX(PL4_TONG_HOP!$G$2:$G$5000,MATCH($C64,PL4_TONG_HOP!$A$2:$A$5000,0)),"")} | G64: =COUNTIFS(FILE_UPLOADS!$B:$B,$A64,FILE_UPLOADS!$D:$D,$C64) -> 0 | H64: =IF(LEN(F64)=0,"",IF(G64>0,"Đã có minh chứng","CHƯA CÓ MINH CHỨNG"))
A65: DV02 | B65: Sở Tài chính | C65: R41 | D65: B.1.1.3 | E65: B.1.1.3. Kết quả thực hiện công khai, minh bạch tuyển dụng, bổ nhiệm công chức, viên chức | F65: {=IFERROR(INDEX(PL4_TONG_HOP!$G$2:$G$5000,MATCH($C65,PL4_TONG_HOP!$A$2:$A$5000,0)),"")} | G65: =COUNTIFS(FILE_UPLOADS!$B:$B,$A65,FILE_UPLOADS!$D:$D,$C65) -> 0 | H65: =IF(LEN(F65)=0,"",IF(G65>0,"Đã có minh chứng","CHƯA CÓ MINH CHỨNG"))
... A105: DV02 | B105: Sở Tài chính | C105: R106 | D105: ĐT.3 | E105: ĐT.3. Người đứng đầu, cấp phó của người đứng đầu cấp tỉnh bị xử lý do để xảy ra tham nhũng, tiêu cực năm 2025 | F105: {=IFERROR(INDEX(PL4_TONG_HOP!$G$2:$G$5000,MATCH($C105,PL4_TONG_HOP!$A$2:$A$5000,0)),"")} | G105: =COUNTIFS(FILE_UPLOADS!$B:$B,$A105,FILE_UPLOADS!$D:$D,$C105) -> 0 | H105: =IF(LEN(F105)=0,"",IF(G105>0,"Đã có minh chứng","CHƯA CÓ MINH CHỨNG"))
A106: DV03 | B106: Sở Nông nghiệp và Môi trường | C106: R17 | D106: A.1.2 | E106: A.1.2. Ban hành kế hoạch PCTN năm 2025 | F106: {=IFERROR(INDEX(PL4_TONG_HOP!$H$2:$H$5000,MATCH($C106,PL4_TONG_HOP!$A$2:$A$5000,0)),"")} | G106: =COUNTIFS(FILE_UPLOADS!$B:$B,$A106,FILE_UPLOADS!$D:$D,$C106) -> 0 | H106: =IF(LEN(F106)=0,"",IF(G106>0,"Đã có minh chứng","CHƯA CÓ MINH CHỨNG"))
A107: DV03 | B107: Sở Nông nghiệp và Môi trường | C107: R27 | D107: A.2.1.1 | E107: A.2.1.1. Ban hành kế hoạch | F107: {=IFERROR(INDEX(PL4_TONG_HOP!$H$2:$H$5000,MATCH($C107,PL4_TONG_HOP!$A$2:$A$5000,0)),"")} | G107: =COUNTIFS(FILE_UPLOADS!$B:$B,$A107,FILE_UPLOADS!$D:$D,$C107) -> 0 | H107: =IF(LEN(F107)=0,"",IF(G107>0,"Đã có minh chứng","CHƯA CÓ MINH CHỨNG"))
A108: DV03 | B108: Sở Nông nghiệp và Môi trường | C108: R28 | D108: A.2.1.2 | E108: A.2.1.2. Kết quả thực hiện | F108: {=IFERROR(INDEX(PL4_TONG_HOP!$H$2:$H$5000,MATCH($C108,PL4_TONG_HOP!$A$2:$A$5000,0)),"")} | G108: =COUNTIFS(FILE_UPLOADS!$B:$B,$A108,FILE_UPLOADS!$D:$D,$C108) -> 0 | H108: =IF(LEN(F108)=0,"",IF(G108>0,"Đã có minh chứng","CHƯA CÓ MINH CHỨNG"))
A109: DV03 | B109: Sở Nông nghiệp và Môi trường | C109: R30 | D109: A.2.2.1 | E109: A.2.2.1. Ban hành kế hoạch | F109: {=IFERROR(INDEX(PL4_TONG_HOP!$H$2:$H$5000,MATCH($C109,PL4_TONG_HOP!$A$2:$A$5000,0)),"")} | G109: =COUNTIFS(FILE_UPLOADS!$B:$B,$A109,FILE_UPLOADS!$D:$D,$C109) -> 0 | H109: =IF(LEN(F109)=0,"",IF(G109>0,"Đã có minh chứng","CHƯA CÓ MINH CHỨNG"))
A110: DV03 | B110: Sở Nông nghiệp và Môi trường | C110: R31 | D110: A.2.2.2 | E110: A.2.2.2. Kết quả thực hiện | F110: {=IFERROR(INDEX(PL4_TONG_HOP!$H$2:$H$5000,MATCH($C110,PL4_TONG_HOP!$A$2:$A$5000,0)),"")} | G110: =COUNTIFS(FILE_UPLOADS!$B:$B,$A110,FILE_UPLOADS!$D:$D,$C110) -> 0 | H110: =IF(LEN(F110)=0,"",IF(G110>0,"Đã có minh chứng","CHƯA CÓ MINH CHỨNG"))
A111: DV03 | B111: Sở Nông nghiệp và Môi trường | C111: R32 | D111: A.2.3 | E111: A.2.3. Thực hiện việc kiểm tra và theo dõi thi hành văn bản quy phạm pháp luật về PCTN | F111: {=IFERROR(INDEX(PL4_TONG_HOP!$H$2:$H$5000,MATCH($C111,PL4_TONG_HOP!$A$2:$A$5000,0)),"")} | G111: =COUNTIFS(FILE_UPLOADS!$B:$B,$A111,FILE_UPLOADS!$D:$D,$C111) -> 0 | H111: =IF(LEN(F111)=0,"",IF(G111>0,"Đã có minh chứng","CHƯA CÓ MINH CHỨNG"))
A112: DV03 | B112: Sở Nông nghiệp và Môi trường | C112: R33 | D112: A.2.4 | E112: A.2.4. Tiếp công dân theo quy định của Luật tiếp công dân của Chủ tịch UBND cấp tỉnh | F112: {=IFERROR(INDEX(PL4_TONG_HOP!$H$2:$H$5000,MATCH($C112,PL4_TONG_HOP!$A$2:$A$5000,0)),"")} | G112: =COUNTIFS(FILE_UPLOADS!$B:$B,$A112,FILE_UPLOADS!$D:$D,$C112) -> 0 | H112: =IF(LEN(F112)=0,"",IF(G112>0,"Đã có minh chứng","CHƯA CÓ MINH CHỨNG"))
A113: DV03 | B113: Sở Nông nghiệp và Môi trường | C113: R34 | D113: A.2.5 | E113: A.2.5. Tiếp công dân theo quy định của Luật tiếp công dân của Người đứng đầu cơ quan chuyên môn thuộc UBND cấp Tỉnh | F113: {=IFERROR(INDEX(PL4_TONG_HOP!$H$2:$H$5000,MATCH($C113,PL4_TONG_HOP!$A$2:$A$5000,0)),"")} | G113: =COUNTIFS(FILE_UPLOADS!$B:$B,$A113,FILE_UPLOADS!$D:$D,$C113) -> 0 | H113: =IF(LEN(F113)=0,"",IF(G113>0,"Đã có minh chứng","CHƯA CÓ MINH CHỨNG"))
A114: DV03 | B114: Sở Nông nghiệp và Môi trường | C114: R35 | D114: A.2.6 | E114: A.2.6. Việc chỉ đạo của Chủ tịch UBND cấp tỉnh xử lý tố cáo, kiến nghị, phản ánh của công dân về tham nhũng. | F114: {=IFERROR(INDEX(PL4_TONG_HOP!$H$2:$H$5000,MATCH($C114,PL4_TONG_HOP!$A$2:$A$5000,0)),"")} | G114: =COUNTIFS(FILE_UPLOADS!$B:$B,$A114,FILE_UPLOADS!$D:$D,$C114) -> 0 | H114: =IF(LEN(F114)=0,"",IF(G114>0,"Đã có minh chứng","CHƯA CÓ MINH CHỨNG"))
A115: DV03 | B115: Sở Nông nghiệp và Môi trường | C115: R39 | D115: B.1.1.1 | E115: B.1.1.1. Kết quả thực hiện công khai, minh bạch các thủ tục hành chính | F115: {=IFERROR(INDEX(PL4_TONG_HOP!$H$2:$H$5000,MATCH($C115,PL4_TONG_HOP!$A$2:$A$5000,0)),"")} | G115: =COUNTIFS(FILE_UPLOADS!$B:$B,$A115,FILE_UPLOADS!$D:$D,$C115) -> 0 | H115: =IF(LEN(F115)=0,"",IF(G115>0,"Đã có minh chứng","CHƯA CÓ MINH CHỨNG"))
A116: DV03 | B116: Sở Nông nghiệp và Môi trường | C116: R40 | D116: B.1.1.2 | E116: B.1.1.2. Kết quả thực hiện công khai, minh bạch quy tắc ứng xử của người có chức vụ quyền hạn | F116: {=IFERROR(INDEX(PL4_TONG_HOP!$H$2:$H$5000,MATCH($C116,PL4_TONG_HOP!$A$2:$A$5000,0)),"")} | G116: =COUNTIFS(FILE_UPLOADS!$B:$B,$A116,FILE_UPLOADS!$D:$D,$C116) -> 0 | H116: =IF(LEN(F116)=0,"",IF(G116>0,"Đã có minh chứng","CHƯA CÓ MINH CHỨNG"))
A117: DV03 | B117: Sở Nông nghiệp và Môi trường | C117: R41 | D117: B.1.1.3 | E117: B.1.1.3. Kết quả thực hiện công khai, minh bạch tuyển dụng, bổ nhiệm công chức, viên chức | F117: {=IFERROR(INDEX(PL4_TONG_HOP!$H$2:$H$5000,MATCH($C117,PL4_TONG_HOP!$A$2:$A$5000,0)),"")} | G117: =COUNTIFS(FILE_UPLOADS!$B:$B,$A117,FILE_UPLOADS!$D:$D,$C117) -> 0 | H117: =IF(LEN(F117)=0,"",IF(G117>0,"Đã có minh chứng","CHƯA CÓ MINH CHỨNG"))
... A157: DV03 | B157: Sở Nông nghiệp và Môi trường | C157: R106 | D157: ĐT.3 | E157: ĐT.3. Người đứng đầu, cấp phó của người đứng đầu cấp tỉnh bị xử lý do để xảy ra tham nhũng, tiêu cực năm 2025 | F157: {=IFERROR(INDEX(PL4_TONG_HOP!$H$2:$H$5000,MATCH($C157,PL4_TONG_HOP!$A$2:$A$5000,0)),"")} | G157: =COUNTIFS(FILE_UPLOADS!$B:$B,$A157,FILE_UPLOADS!$D:$D,$C157) -> 0 | H157: =IF(LEN(F157)=0,"",IF(G157>0,"Đã có minh chứng","CHƯA CÓ MINH CHỨNG"))
...

Sheet DM_DON_VI
A1: MA_DON_VI | B1: TEN_DON_VI | C1: TEN_FOLDER_DRIVE | D1: LINK_THU_MUC_DRIVE
A2: DV01 | B2: Văn phòng UBND tỉnh | C2: DV01_VanPhong_UBND_tinh | D2: https://drive.google.com/drive/folders/1hsz0Aa0ULK1UtLKQh_g5tNXdg94-WCaJ
A3: DV02 | B3: Sở Tài chính | C3: DV02_So_Tai_chinh | D3: https://drive.google.com/drive/folders/1riNtH7lfdBB0buPuCIEgiGZlr3kDz9Ee
A4: DV03 | B4: Sở Nông nghiệp và Môi trường | C4: DV03_So_Nong_nghiep_va_Moi_truong | D4: https://drive.google.com/drive/folders/1pCFapIIqtoPqcoV8Cs_Snujs3y-RB_nd
A5: DV04 | B5: Sở Xây dựng | C5: DV04_So_Xay_dung | D5: https://drive.google.com/drive/folders/11urXEHb_Dob_bC5OG0wc6vPW3sfAKcfm
A6: DV05 | B6: Sở Tư pháp | C6: DV05_So_Tu_phap | D6: https://drive.google.com/drive/folders/13YcBM0P7OK2_cPfSytTNEy585KruY6UF
A7: DV06 | B7: Sở Công thương | C7: DV06_So_Cong_thuong | D7: https://drive.google.com/drive/folders/10ZAafPKU2E2ChzEZsNtkhAD86THG8ziv
A8: DV07 | B8: Sở Văn hóa thể thao và Du lịch | C8: DV07_So_Van_hoa_the_thao_va_Du_lich | D8: https://drive.google.com/drive/folders/1m540wro01LH-xHVm52OEfEO-PyJDOSL5
A9: DV08 | B9: Sở Giáo dục và Đào tạo | C9: DV08_So_Giao_duc_va_Dao_tao | D9: https://drive.google.com/drive/folders/1BoCjXx_glHc3ZVP8iSygo9mF7qLwtCmL
A10: DV09 | B10: Sở Khoa học và Công nghệ | C10: DV09_So_Khoa_hoc_va_Cong_nghe | D10: https://drive.google.com/drive/folders/1Cj6VsKoh0twqPxE_Pv7z7vsQlTulfj5F
A11: DV10 | B11: Sở Y tế | C11: DV10_So_Y_te | D11: https://drive.google.com/drive/folders/1FSBFLilxPI-HEkCiaa5cwz4jXq85cWBE
A12: DV11 | B12: Sở Nội vụ | C12: DV11_So_Noi_vu | D12: https://drive.google.com/drive/folders/1Pqy0-uyVI9b-ZuFs49nKmUvXhmgIQDQa
... A17: DV16 | B17: Viện quy hoạch kiến trúc Thanh Hóa | C17: DV16_Vien_quy_hoach_kien_truc_Thanh_Hoa | D17: https://drive.google.com/drive/folders/1RKIYgf4AvyfcmyELAca5XbqLwuSp_mIs

Sheet DM_TIEU_CHI
A1: ROW_ID | B1: MA_TIEU_CHI | C1: NOI_DUNG_TIEU_CHI | D1: CAP_TIEU_CHI | E1: CO_NHAP_LIEU
A2: R9 | B2: A | C2: A. TIÊU CHÍ ĐÁNH GIÁ VIỆC LÃNH ĐẠO, CHỈ ĐẠO, XÂY DỰNG VÀ HOÀN THIỆN CHÍNH SÁCH, PHÁP LUẬT VỀ PCTN | D2: 1 | E2: Không
A3: R10 | B3: A.1 | C3: A.1. Đánh giá việc lãnh đạo, chỉ đạo công tác PCTN: | D3: 2 | E3: Không
A4: R11 | B4: A.1.1 | C4: A.1.1. Triển khai thực hiện các văn bản của các cơ quan ở Trung ương về PCTN trong năm 2025 | D4: 3 | E4: Không
A5: R12 | B5: A.1.1.1 | C5: A.1.1.1. Triển khai thực hiện Chương trình công tác năm 2025 của Ban Chỉ đạo Trung ương về phòng, chống tham nhũng, tiêu cực. | D5: 4 | E5: Không
A6: R13 | B6: A.1.1.2 | C6: A.1.1.2. Triển khai thực hiện Nghị quyết số 168/NQ-CP ngày 11/10/2023 về Chiến lược quốc gia phòng, chống tham nhũng, tiêu cực đến năm 2030. | D6: 4 | E6: Không
A7: R14 | B7: A.1.1.3 | C7: A.1.1.3. Triển khai thực hiện Quy định số 132-QĐ/TW ngày 27/10/2023 của Bộ Chính trị về kiểm soát quyền lực và phòng, chống tham nhũng, tiêu cực trong hoạt động điều tra, truy tố, xét xử, thi hành án. | D7: 4 | E7: Không
A8: R15 | B8: A.1.1.4 | C8: A.1.1.4. Triển khai thực hiện Quy định số 131-QĐ/TW ngày 27/10/2023 của Bộ Chính trị về kiểm soát quyền lực và PCTNTC trong hoạt động kiểm tra, giám sát và thi hành kỷ luật đảng và trong hoạt động thanh tra, kiểm toán. | D8: 4 | E8: Không
A9: R16 | B9: A.1.1.5 | C9: A.1.1.5. Triển khai thực hiện Quy định số 178-QĐ/TW ngày 27/6/2024 của Bộ Chính trị về kiểm soát quyền lực, PCTNTC trong công tác xây dựng pháp luật. | D9: 4 | E9: Không
A10: R17 | B10: A.1.2 | C10: A.1.2. Ban hành kế hoạch PCTN năm 2025 | D10: 3 | E10: Có
A11: R18 | B11: A.1.3 | C11: A.1.3. Nội dung kế hoạch PCTN năm 2025 | D11: 3 | E11: Không
A12: R19 | B12: A.1.3.1 | C12: A.1.3.1. Về thực hiện các chỉ thị, nghị quyết của Trung ương về PCTN | D12: 4 | E12: Không
A13: R20 | B13: A.1.3.2 | C13: A.1.3.2. Về kiểm tra, rà soát, hệ thống hóa văn bản quy phạm pháp luật về PCTN | D13: 4 | E13: Không
... A99: R106 | B99: ĐT.3 | C99: ĐT.3. Người đứng đầu, cấp phó của người đứng đầu cấp tỉnh bị xử lý do để xảy ra tham nhũng, tiêu cực năm 2025 | D99: 2 | E99: Có

Sheet FORM_DATA
A1: TIMESTAMP | B1: MA_DON_VI | C1: TEN_DON_VI | D1: NGUOI_NHAP | E1: DIEN_THOAI | F1: EMAIL | G1: ROW_ID | H1: MA_TIEU_CHI | I1: NOI_DUNG_TIEU_CHI | J1: CAP_TIEU_CHI | K1: CO_NHAP_LIEU | L1: SO_LIEU_MINH_CHUNG | M1: TRANG_THAI_GUI
A2: 46128.033 | B2: DV13 | C2: Thanh tra tỉnh | D2: d | E2: d | F2: d | G2: R17 | H2: A.1.2 | I2: A.1.2. Ban hành kế hoạch PCTN năm 2025 | J2: 3 | K2: TRUE | L2: dsfds | M2: Đã gửi
A3: 46128.033 | B3: DV13 | C3: Thanh tra tỉnh | D3: d | E3: d | F3: d | G3: R27 | H3: A.2.1.1 | I3: A.2.1.1. Ban hành kế hoạch | J3: 4 | K3: TRUE | M3: Đã gửi
A4: 46128.033 | B4: DV13 | C4: Thanh tra tỉnh | D4: d | E4: d | F4: d | G4: R28 | H4: A.2.1.2 | I4: A.2.1.2. Kết quả thực hiện | J4: 4 | K4: TRUE | M4: Đã gửi
A5: 46128.033 | B5: DV13 | C5: Thanh tra tỉnh | D5: d | E5: d | F5: d | G5: R30 | H5: A.2.2.1 | I5: A.2.2.1. Ban hành kế hoạch | J5: 4 | K5: TRUE | M5: Đã gửi
A6: 46128.033 | B6: DV13 | C6: Thanh tra tỉnh | D6: d | E6: d | F6: d | G6: R31 | H6: A.2.2.2 | I6: A.2.2.2. Kết quả thực hiện | J6: 4 | K6: TRUE | M6: Đã gửi
A7: 46128.033 | B7: DV13 | C7: Thanh tra tỉnh | D7: d | E7: d | F7: d | G7: R32 | H7: A.2.3 | I7: A.2.3. Thực hiện việc kiểm tra và theo dõi thi hành văn bản quy phạm pháp luật về PCTN | J7: 3 | K7: TRUE | M7: Đã gửi
A8: 46128.033 | B8: DV13 | C8: Thanh tra tỉnh | D8: d | E8: d | F8: d | G8: R33 | H8: A.2.4 | I8: A.2.4. Tiếp công dân theo quy định của Luật tiếp công dân của Chủ tịch UBND cấp tỉnh | J8: 3 | K8: TRUE | M8: Đã gửi
A9: 46128.033 | B9: DV13 | C9: Thanh tra tỉnh | D9: d | E9: d | F9: d | G9: R34 | H9: A.2.5 | I9: A.2.5. Tiếp công dân theo quy định của Luật tiếp công dân của Người đứng đầu cơ quan chuyên môn thuộc UBND cấp Tỉnh | J9: 3 | K9: TRUE | M9: Đã gửi
A10: 46128.033 | B10: DV13 | C10: Thanh tra tỉnh | D10: d | E10: d | F10: d | G10: R35 | H10: A.2.6 | I10: A.2.6. Việc chỉ đạo của Chủ tịch UBND cấp tỉnh xử lý tố cáo, kiến nghị, phản ánh của công dân về tham nhũng. | J10: 3 | K10: TRUE | M10: Đã gửi
A11: 46128.033 | B11: DV13 | C11: Thanh tra tỉnh | D11: d | E11: d | F11: d | G11: R39 | H11: B.1.1.1 | I11: B.1.1.1. Kết quả thực hiện công khai, minh bạch các thủ tục hành chính | J11: 4 | K11: TRUE | M11: Đã gửi
A12: 46128.033 | B12: DV13 | C12: Thanh tra tỉnh | D12: d | E12: d | F12: d | G12: R40 | H12: B.1.1.2 | I12: B.1.1.2. Kết quả thực hiện công khai, minh bạch quy tắc ứng xử của người có chức vụ quyền hạn | J12: 4 | K12: TRUE | M12: Đã gửi
A13: 46128.033 | B13: DV13 | C13: Thanh tra tỉnh | D13: d | E13: d | F13: d | G13: R41 | H13: B.1.1.3 | I13: B.1.1.3. Kết quả thực hiện công khai, minh bạch tuyển dụng, bổ nhiệm công chức, viên chức | J13: 4 | K13: TRUE | M13: Đã gửi
A14: 46128.033 | B14: DV13 | C14: Thanh tra tỉnh | D14: d | E14: d | F14: d | G14: R42 | H14: B.1.1.4 | I14: B.1.1.4. Kết quả thực hiện công khai, minh bạch về ngân sách Nhà nước | J14: 4 | K14: TRUE | M14: Đã gửi
... A53: 46128.033 | B53: DV13 | C53: Thanh tra tỉnh | D53: d | E53: d | F53: d | G53: R106 | H53: ĐT.3 | I53: ĐT.3. Người đứng đầu, cấp phó của người đứng đầu cấp tỉnh bị xử lý do để xảy ra tham nhũng, tiêu cực năm 2025 | J53: 2 | K53: TRUE | M53: Đã gửi

Sheet FILE_UPLOADS
A1: TIMESTAMP | B1: MA_DON_VI | C1: TEN_DON_VI | D1: ROW_ID | E1: MA_TIEU_CHI | F1: TEN_TIEU_CHI | G1: FILE_NAME | H1: FILE_URL | I1: FILE_ID | J1: MIME_TYPE | K1: FILE_SIZE | L1: FOLDER_NAME | M1: FOLDER_URL | N1: NGUOI_NHAP | O1: DIEN_THOAI | P1: EMAIL | Q1: TRANG_THAI
A2: 46128.033 | B2: DV13 | C2: Thanh tra tỉnh | D2: R17 | E2: A.1.2 | F2: A.1.2. Ban hành kế hoạch PCTN năm 2025 | G2: DV13_A-1-2_20260416_144738_BC tham dự lớp bồi dưỡng theo CV1371.pdf | H2: https://drive.google.com/file/d/1qjewhK1MLO9m8VU87mfdgn0x7WrsahIk/view?usp=drivesdk | I2: 1qjewhK1MLO9m8VU87mfdgn0x7WrsahIk | J2: application/pdf | K2: 837747 | L2: A-1-2 | M2: https://drive.google.com/drive/folders/19aXF_QPg3M-RX67gnVV1Vum72zDtv5rO | N2: d | O2: d | P2: d | Q2: ACTIVE

Sheet HUONG_DAN
A1: TÀI LIỆU NỀN PACA 2025 - BẢN CẬP NHẬT DANH SÁCH 16 ĐƠN VỊ
A2: 1. Sheet DM_TIEU_CHI đã đồng bộ với file HTML hiện hành.
A3: 2. Dòng nào CO_NHAP_LIEU = Không thì chỉ là tiêu đề, không nhập.
A4: 3. Sheet PL4_TONG_HOP dùng để tổng hợp theo cột đơn vị.
A5: 4. Sheet FORM_DATA lưu từng lần gửi từ Web App.
A6: 5. HTML mới có chức năng Gửi dữ liệu và Lấy dữ liệu đã nhập trước đó.
