Workbook

Sheet 01_PCTN_TONGHOP
A1: BIỂU 01/PCTN
A2: TỔNG HỢP KẾT QUẢ THỰC HIỆN CÔNG TÁC PHÒNG, CHỐNG THAM NHŨNG, LÃNG PHÍ, TIÊU CỰC
C3: QUÝ….NĂM……. (từ ngày…./…../2026 đến....ngày…../…../2026)
A4: STT | B4: MS | C4: Nội dung | D4: ĐVT | E4: Tổng toàn tỉnh | F4: Ghi chú | G4: Mã kỹ thuật | H4: Loại dòng | L4: Văn phòng UBND | M4: Sở Tài chính | N4: Sở Nông nghiệp và Môi trường | O4: Sở Xây dựng | P4: Sở Tư pháp | Q4: Sở Công thương | R4: Sở Văn hóa TT và DL | S4: Sở Giáo dục và Đào tạo | T4: Sở Khoa học và Công nghệ | U4: Sở Y tế | V4: Sở Nội vụ | W4: Sở Ngoại vụ | X4: Thanh tra tỉnh | Y4: Sở Dân tộc và Tôn giáo | Z4: Ban Quản lý KKTNS và Các KCN | AA4: Báo và Đài phát thanh truyền hình TH | AB4: Phường Bỉm Sơn | AC4: Phường Đào Duy Từ | AD4: Phường Đông Quang | AE4: Phường Đông Sơn | AF4: Phường Đông Tiến | AG4: Phường Hạc Thành | AH4: Phường Hải Bình | AI4: Phường Hải Lĩnh | AJ4: Phường Hàm Rồng | AK4: Phường Nam Sầm Sơn | AL4: Phường Nghi Sơn | AM4: Phường Ngọc Sơn | AN4: Phường Nguyệt Viên | AO4: Phường Quảng Phú | AP4: Phường Quang Trung | AQ4: Phường Sầm Sơn | AR4: Phường Tân Dân | AS4: Phường Tĩnh Gia | AT4: Phường Trúc Lâm | AU4: Xã An Nông | AV4: Xã Ba Đình | AW4: Xã Bá Thước | AX4: Xã Bát Mọt | AY4: Xã Biện Thượng | AZ4: Xã Các Sơn | BA4: Xã Cẩm Tân | BB4: Xã Cẩm Tú | BC4: Xã Cẩm Thạch | BD4: Xã Cẩm Thủy | BE4: Xã Cẩm Vân | BF4: Xã Cổ Lũng | BG4: Xã Công Chính | BH4: Xã Điền Lư | BI4: Xã Điền Quang | BJ4: Xã Định Hòa | BK4: Xã Định Tân | BL4: Xã Đồng Lương | BM4: Xã Đồng Tiến | BN4: Xã Đông Thành | BO4: Xã Giao An | BP4: Xã Hà Long | BQ4: Xã Hà Trung | BR4: Xã Hậu Lộc | BS4: Xã Hiền Kiệt | BT4: Xã Hoa Lộc | BU4: Xã Hóa Quỳ | BV4: Xã Hoạt Giang | BW4: Xã Hoằng Châu | BX4: Xã Hoằng Giang | BY4: Xã Hoằng Hóa | BZ4: Xã Hoằng Lộc | CA4: Xã Hoằng Phú | CB4: Xã Hoằng Sơn | CC4: Xã Hoằng Tiến | CD4: Xã Hoằng Thanh | CE4: Xã Hồ Vương | CF4: Xã Hồi Xuân | CG4: Xã Hợp Tiến | CH4: Xã Kiên Thọ | CI4: Xã Kim Tân | CJ4: Xã Lam Sơn | CK4: Xã Linh Sơn | CL4: Xã Lĩnh Toại | CM4: Xã Luận Thành | CN4: Xã Lương Sơn | CO4: Xã Lưu Vệ | CP4: Xã Mậu Lâm | CQ4: Xã Minh Sơn | CR4: Xã Mường Chanh | CS4: Xã Mường Lát | CT4: Xã Mường Lý | CU4: Xã Mường Mìn | CV4: Xã Na Mèo | CW4: Xã Nam Xuân | CX4: Xã Nông Cống | CY4: Xã Nga An | CZ4: Xã Nga Sơn | DA4: Xã Nga Thắng | DB4: Xã Ngọc Lặc | DC4: Xã Ngọc Liên | DD4: Xã Ngọc Trạo | DE4: Xã Nguyệt Ấn | DF4: Xã Nhi Sơn | DG4: Xã Như Thanh | DH4: Xã Như Xuân | DI4: Xã Pù Luông | DJ4: Xã Pù Nhi | DK4: Xã Phú Lệ | DL4: Xã Phú Xuân (Quan Hóa) | DM4: Xã Quan Sơn | DN4: Xã Quảng Bình | DO4: Xã Quang Chiểu | DP4: Xã Quảng Chính | DQ4: Xã Quảng Ninh | DR4: Xã Quảng Ngọc | DS4: Xã Quảng Yên | DT4: Xã Quý Lộc | DU4: Xã Quý Lương | DV4: Xã Sao Vàng | DW4: Xã Sơn Điện | DX4: Xã Sơn Thủy | DY4: Xã Tam Chung | DZ4: Xã Tam Lư | EA4: Xã Tam Thanh | EB4: Xã Tân Ninh | EC4: Xã Tân Tiến | ED4: Xã Tân Thành | EE4: Xã Tây Đô | EF4: Xã Tiên Trang | EG4: Xã Tống Sơn | EH4: Xã Tượng Lĩnh | EI4: Xã Thạch Bình | EJ4: Xã Thạch Lập | EK4: Xã Thạch Quảng | EL4: Xã Thanh Kỳ | EM4: Xã Thanh Phong | EN4: Xã Thanh Quân | EO4: Xã Thành Vinh | EP4: Xã Thăng Bình | EQ4: Xã Thắng Lộc | ER4: Xã Thắng Lợi | ES4: Xã Thiên Phủ | ET4: Xã Thiết Ống | EU4: Xã Thiệu Hóa | EV4: Xã Thiệu Quang | EW4: Xã Thiệu Tiến | EX4: Xã Thiệu Toán | EY4: Xã Thiệu Trung | EZ4: Xã Thọ Bình | FA4: Xã Thọ Lập | FB4: Xã Thọ Long | FC4: Xã Thọ Ngọc | FD4: Xã Thọ Phú | FE4: Xã Thọ Xuân | FF4: Xã Thượng Ninh | FG4: Xã Thường Xuân | FH4: Xã Triệu Lộc | FI4: Xã Triệu Sơn | FJ4: Xã Trung Chính | FK4: Xã Trung Hạ | FL4: Xã Trung Lý | FM4: Xã Trung Sơn | FN4: Xã Trung Thành | FO4: Xã Trường Lâm | FP4: Xã Trường Văn | FQ4: Xã Vạn Lộc | FR4: Xã Vạn Xuân | FS4: Xã Văn Nho | FT4: Xã Văn Phú | FU4: Xã Vân Du | FV4: Xã Vĩnh Lộc | FW4: Xã Xuân Bình | FX4: Xã Xuân Chinh | FY4: Xã Xuân Du | FZ4: Xã Xuân Hòa | GA4: Xã Xuân Lập | GB4: Xã Xuân Tín | GC4: Xã Xuân Thái | GD4: Xã Yên Định | GE4: Xã Yên Khương | GF4: Xã Yên Ninh | GG4: Xã Yên Nhân | GH4: Xã Yên Phú | GI4: Xã Yên Thắng | GJ4: Xã Yên Thọ | GK4: Xã Yên Trường
A5: CHÍNH SÁCH, PHÁP LUẬT | H5: SECTION | I5: CHÍNH SÁCH, PHÁP LUẬT
A6: 1 | B6: 1 | C6: Số văn bản ban hành mới để thực hiện Luật PCTN và các văn bản hướng dẫn thi hành Luật PCTN | D6: Văn bản | E6: {=SUMPRODUCT(IFERROR(INDEX('01_PCTN_DATA'!$A$4:$ZZ$1000,0,MATCH($G6,'01_PCTN_DATA'!$A$3:$ZZ$3,0)),0))} -> 0 | G6: P01_1 | H6: ITEM | I6: CHÍNH SÁCH, PHÁP LUẬT | K6: 1 | L6: {=SUMPRODUCT(('01_PCTN_DATA'!$A$4:$A$1000=IFERROR(INDEX(DM_DON_VI!$B$4:$B$185,MATCH(L$4,DM_DON_VI!$D$4:$D$185,0)),""))*IFERROR(INDEX('01_PCTN_DATA'!$A$4:$ZZ$1000,0,MATCH($G6,'01_PCTN_DATA'!$A$3:$ZZ$3,0)),0))} -> 0 | M6: {=SUMPRODUCT(('01_PCTN_DATA'!$A$4:$A$1000=IFERROR(INDEX(DM_DON_VI!$B$4:$B$185,MATCH(M$4,DM_DON_VI!$D$4:$D$185,0)),""))*IFERROR(INDEX('01_PCTN_DATA'!$A$4:$ZZ$1000,0,MATCH($G6,'01_PCTN_DATA'!$A$3:$ZZ$3,0)),0))} -> 0 | N6: {=SUMPRODUCT(('01_PCTN_DATA'!$A$4:$A$1000=IFERROR(INDEX(DM_DON_VI!$B$4:$B$185,MATCH(N$4,DM_DON_VI!$D$4:$D$185,0)),""))*IFERROR(INDEX('01_PCTN_DATA'!$A$4:$ZZ$1000,0,MATCH($G6,'01_PCTN_DATA'!$A$3:$ZZ$3,0)),0))} -> 0 | O6: {=SUMPRODUCT(('01_PCTN_DATA'!$A$4:$A$1000=IFERROR(INDEX(DM_DON_VI!$B$4:$B$185,MATCH(O$4,DM_DON_VI!$D$4:$D$185,0)),""))*IFERROR(INDEX('01_PCTN_DATA'!$A$4:$ZZ$1000,0,MATCH($G6,'01_PCTN_DATA'!$A$3:$ZZ$3,0)),0))} -> 0 | P6: {=SUMPRODUCT(('01_PCTN_DATA'!$A$4:$A$1000=IFERROR(INDEX(DM_DON_VI!$B$4:$B$185,MATCH(P$4,DM_DON_VI!$D$4:$D$185,0)),""))*IFERROR(INDEX('01_PCTN_DATA'!$A$4:$ZZ$1000,0,MATCH($G6,'01_PCTN_DATA'!$A$3:$ZZ$3,0)),0))} -> 0 | Q6: {=SUMPRODUCT(('01_PCTN_DATA'!$A$4:$A$1000=IFERROR(INDEX(DM_DON_VI!$B$4:$B$185,MATCH(Q$4,DM_DON_VI!$D$4:$D$185,0)),""))*IFERROR(INDEX('01_PCTN_DATA'!$A$4:$ZZ$1000,0,MATCH($G6,'01_PCTN_DATA'!$A$3:$ZZ$3,0)),0))} -> 0 | R6: {=SUMPRODUCT(('01_PCTN_DATA'!$A$4:$A$1000=IFERROR(INDEX(DM_DON_VI!$B$4:$B$185,MATCH(R$4,DM_DON_VI!$D$4:$D$185,0)),""))*IFERROR(INDEX('01_PCTN_DATA'!$A$4:$ZZ$1000,0,MATCH($G6,'01_PCTN_DATA'!$A$3:$ZZ$3,0)),0))} -> 0 | S6: {=SUMPRODUCT(('01_PCTN_DATA'!$A$4:$A$1000=IFERROR(INDEX(DM_DON_VI!$B$4:$B$185,MATCH(S$4,DM_DON_VI!$D$4:$D$185,0)),""))*IFERROR(INDEX('01_PCTN_DATA'!$A$4:$ZZ$1000,0,MATCH($G6,'01_PCTN_DATA'!$A$3:$ZZ$3,0)),0))} -> 0 | ... GK6: {=SUMPRODUCT(('01_PCTN_DATA'!$A$4:$A$1000=IFERROR(INDEX(DM_DON_VI!$B$4:$B$185,MATCH(GK$4,DM_DON_VI!$D$4:$D$185,0)),""))*IFERROR(INDEX('01_PCTN_DATA'!$A$4:$ZZ$1000,0,MATCH($G6,'01_PCTN_DATA'!$A$3:$ZZ$3,0)),0))} -> 0
A7: 2 | B7: 2 | C7: Số văn bản được sửa đổi, bổ sung để thực hiện Luật PCTN và các văn bản hướng dẫn thi hành | D7: Văn bản | E7: {=SUMPRODUCT(IFERROR(INDEX('01_PCTN_DATA'!$A$4:$ZZ$1000,0,MATCH($G7,'01_PCTN_DATA'!$A$3:$ZZ$3,0)),0))} -> 0 | G7: P01_2 | H7: ITEM | I7: CHÍNH SÁCH, PHÁP LUẬT | K7: 2 | L7: {=SUMPRODUCT(('01_PCTN_DATA'!$A$4:$A$1000=IFERROR(INDEX(DM_DON_VI!$B$4:$B$185,MATCH(L$4,DM_DON_VI!$D$4:$D$185,0)),""))*IFERROR(INDEX('01_PCTN_DATA'!$A$4:$ZZ$1000,0,MATCH($G7,'01_PCTN_DATA'!$A$3:$ZZ$3,0)),0))} -> 0 | M7: {=SUMPRODUCT(('01_PCTN_DATA'!$A$4:$A$1000=IFERROR(INDEX(DM_DON_VI!$B$4:$B$185,MATCH(M$4,DM_DON_VI!$D$4:$D$185,0)),""))*IFERROR(INDEX('01_PCTN_DATA'!$A$4:$ZZ$1000,0,MATCH($G7,'01_PCTN_DATA'!$A$3:$ZZ$3,0)),0))} -> 0 | N7: {=SUMPRODUCT(('01_PCTN_DATA'!$A$4:$A$1000=IFERROR(INDEX(DM_DON_VI!$B$4:$B$185,MATCH(N$4,DM_DON_VI!$D$4:$D$185,0)),""))*IFERROR(INDEX('01_PCTN_DATA'!$A$4:$ZZ$1000,0,MATCH($G7,'01_PCTN_DATA'!$A$3:$ZZ$3,0)),0))} -> 0 | O7: {=SUMPRODUCT(('01_PCTN_DATA'!$A$4:$A$1000=IFERROR(INDEX(DM_DON_VI!$B$4:$B$185,MATCH(O$4,DM_DON_VI!$D$4:$D$185,0)),""))*IFERROR(INDEX('01_PCTN_DATA'!$A$4:$ZZ$1000,0,MATCH($G7,'01_PCTN_DATA'!$A$3:$ZZ$3,0)),0))} -> 0 | P7: {=SUMPRODUCT(('01_PCTN_DATA'!$A$4:$A$1000=IFERROR(INDEX(DM_DON_VI!$B$4:$B$185,MATCH(P$4,DM_DON_VI!$D$4:$D$185,0)),""))*IFERROR(INDEX('01_PCTN_DATA'!$A$4:$ZZ$1000,0,MATCH($G7,'01_PCTN_DATA'!$A$3:$ZZ$3,0)),0))} -> 0 | Q7: {=SUMPRODUCT(('01_PCTN_DATA'!$A$4:$A$1000=IFERROR(INDEX(DM_DON_VI!$B$4:$B$185,MATCH(Q$4,DM_DON_VI!$D$4:$D$185,0)),""))*IFERROR(INDEX('01_PCTN_DATA'!$A$4:$ZZ$1000,0,MATCH($G7,'01_PCTN_DATA'!$A$3:$ZZ$3,0)),0))} -> 0 | R7: {=SUMPRODUCT(('01_PCTN_DATA'!$A$4:$A$1000=IFERROR(INDEX(DM_DON_VI!$B$4:$B$185,MATCH(R$4,DM_DON_VI!$D$4:$D$185,0)),""))*IFERROR(INDEX('01_PCTN_DATA'!$A$4:$ZZ$1000,0,MATCH($G7,'01_PCTN_DATA'!$A$3:$ZZ$3,0)),0))} -> 0 | S7: {=SUMPRODUCT(('01_PCTN_DATA'!$A$4:$A$1000=IFERROR(INDEX(DM_DON_VI!$B$4:$B$185,MATCH(S$4,DM_DON_VI!$D$4:$D$185,0)),""))*IFERROR(INDEX('01_PCTN_DATA'!$A$4:$ZZ$1000,0,MATCH($G7,'01_PCTN_DATA'!$A$3:$ZZ$3,0)),0))} -> 0 | ... GK7: {=SUMPRODUCT(('01_PCTN_DATA'!$A$4:$A$1000=IFERROR(INDEX(DM_DON_VI!$B$4:$B$185,MATCH(GK$4,DM_DON_VI!$D$4:$D$185,0)),""))*IFERROR(INDEX('01_PCTN_DATA'!$A$4:$ZZ$1000,0,MATCH($G7,'01_PCTN_DATA'!$A$3:$ZZ$3,0)),0))} -> 0
A8: 3 | B8: 3 | C8: Số văn bản được bãi bỏ để thực hiện Luật PCTN và các văn bản hướng dẫn thi hành | D8: Văn bản | E8: {=SUMPRODUCT(IFERROR(INDEX('01_PCTN_DATA'!$A$4:$ZZ$1000,0,MATCH($G8,'01_PCTN_DATA'!$A$3:$ZZ$3,0)),0))} -> 0 | G8: P01_3 | H8: ITEM | I8: CHÍNH SÁCH, PHÁP LUẬT | K8: 3 | L8: {=SUMPRODUCT(('01_PCTN_DATA'!$A$4:$A$1000=IFERROR(INDEX(DM_DON_VI!$B$4:$B$185,MATCH(L$4,DM_DON_VI!$D$4:$D$185,0)),""))*IFERROR(INDEX('01_PCTN_DATA'!$A$4:$ZZ$1000,0,MATCH($G8,'01_PCTN_DATA'!$A$3:$ZZ$3,0)),0))} -> 0 | M8: {=SUMPRODUCT(('01_PCTN_DATA'!$A$4:$A$1000=IFERROR(INDEX(DM_DON_VI!$B$4:$B$185,MATCH(M$4,DM_DON_VI!$D$4:$D$185,0)),""))*IFERROR(INDEX('01_PCTN_DATA'!$A$4:$ZZ$1000,0,MATCH($G8,'01_PCTN_DATA'!$A$3:$ZZ$3,0)),0))} -> 0 | N8: {=SUMPRODUCT(('01_PCTN_DATA'!$A$4:$A$1000=IFERROR(INDEX(DM_DON_VI!$B$4:$B$185,MATCH(N$4,DM_DON_VI!$D$4:$D$185,0)),""))*IFERROR(INDEX('01_PCTN_DATA'!$A$4:$ZZ$1000,0,MATCH($G8,'01_PCTN_DATA'!$A$3:$ZZ$3,0)),0))} -> 0 | O8: {=SUMPRODUCT(('01_PCTN_DATA'!$A$4:$A$1000=IFERROR(INDEX(DM_DON_VI!$B$4:$B$185,MATCH(O$4,DM_DON_VI!$D$4:$D$185,0)),""))*IFERROR(INDEX('01_PCTN_DATA'!$A$4:$ZZ$1000,0,MATCH($G8,'01_PCTN_DATA'!$A$3:$ZZ$3,0)),0))} -> 0 | P8: {=SUMPRODUCT(('01_PCTN_DATA'!$A$4:$A$1000=IFERROR(INDEX(DM_DON_VI!$B$4:$B$185,MATCH(P$4,DM_DON_VI!$D$4:$D$185,0)),""))*IFERROR(INDEX('01_PCTN_DATA'!$A$4:$ZZ$1000,0,MATCH($G8,'01_PCTN_DATA'!$A$3:$ZZ$3,0)),0))} -> 0 | Q8: {=SUMPRODUCT(('01_PCTN_DATA'!$A$4:$A$1000=IFERROR(INDEX(DM_DON_VI!$B$4:$B$185,MATCH(Q$4,DM_DON_VI!$D$4:$D$185,0)),""))*IFERROR(INDEX('01_PCTN_DATA'!$A$4:$ZZ$1000,0,MATCH($G8,'01_PCTN_DATA'!$A$3:$ZZ$3,0)),0))} -> 0 | R8: {=SUMPRODUCT(('01_PCTN_DATA'!$A$4:$A$1000=IFERROR(INDEX(DM_DON_VI!$B$4:$B$185,MATCH(R$4,DM_DON_VI!$D$4:$D$185,0)),""))*IFERROR(INDEX('01_PCTN_DATA'!$A$4:$ZZ$1000,0,MATCH($G8,'01_PCTN_DATA'!$A$3:$ZZ$3,0)),0))} -> 0 | S8: {=SUMPRODUCT(('01_PCTN_DATA'!$A$4:$A$1000=IFERROR(INDEX(DM_DON_VI!$B$4:$B$185,MATCH(S$4,DM_DON_VI!$D$4:$D$185,0)),""))*IFERROR(INDEX('01_PCTN_DATA'!$A$4:$ZZ$1000,0,MATCH($G8,'01_PCTN_DATA'!$A$3:$ZZ$3,0)),0))} -> 0 | ... GK8: {=SUMPRODUCT(('01_PCTN_DATA'!$A$4:$A$1000=IFERROR(INDEX(DM_DON_VI!$B$4:$B$185,MATCH(GK$4,DM_DON_VI!$D$4:$D$185,0)),""))*IFERROR(INDEX('01_PCTN_DATA'!$A$4:$ZZ$1000,0,MATCH($G8,'01_PCTN_DATA'!$A$3:$ZZ$3,0)),0))} -> 0
A9: TUYÊN TRUYỀN, PHỔ BIẾN, GIÁO DỤC PHÁP LUẬT VỀ PHÒNG, CHỐNG THAM NHŨNG, TIÊU CỰC | H9: SECTION | I9: TUYÊN TRUYỀN, PHỔ BIẾN, GIÁO DỤC PHÁP LUẬT VỀ PHÒNG, CHỐNG THAM NHŨNG, TIÊU CỰC
A10: 4 | B10: 4 | C10: Số lớp tuyên truyền, quán triệt pháp luật về phòng, chống tham nhũng, tiêu cực được tổ chức | D10: Lớp | E10: {=SUMPRODUCT(IFERROR(INDEX('01_PCTN_DATA'!$A$4:$ZZ$1000,0,MATCH($G10,'01_PCTN_DATA'!$A$3:$ZZ$3,0)),0))} -> 0 | G10: P01_4 | H10: ITEM | I10: TUYÊN TRUYỀN, PHỔ BIẾN, GIÁO DỤC PHÁP LUẬT VỀ PHÒNG, CHỐNG THAM NHŨNG, TIÊU CỰC | K10: 4 | L10: {=SUMPRODUCT(('01_PCTN_DATA'!$A$4:$A$1000=IFERROR(INDEX(DM_DON_VI!$B$4:$B$185,MATCH(L$4,DM_DON_VI!$D$4:$D$185,0)),""))*IFERROR(INDEX('01_PCTN_DATA'!$A$4:$ZZ$1000,0,MATCH($G10,'01_PCTN_DATA'!$A$3:$ZZ$3,0)),0))} -> 0 | M10: {=SUMPRODUCT(('01_PCTN_DATA'!$A$4:$A$1000=IFERROR(INDEX(DM_DON_VI!$B$4:$B$185,MATCH(M$4,DM_DON_VI!$D$4:$D$185,0)),""))*IFERROR(INDEX('01_PCTN_DATA'!$A$4:$ZZ$1000,0,MATCH($G10,'01_PCTN_DATA'!$A$3:$ZZ$3,0)),0))} -> 0 | N10: {=SUMPRODUCT(('01_PCTN_DATA'!$A$4:$A$1000=IFERROR(INDEX(DM_DON_VI!$B$4:$B$185,MATCH(N$4,DM_DON_VI!$D$4:$D$185,0)),""))*IFERROR(INDEX('01_PCTN_DATA'!$A$4:$ZZ$1000,0,MATCH($G10,'01_PCTN_DATA'!$A$3:$ZZ$3,0)),0))} -> 0 | O10: {=SUMPRODUCT(('01_PCTN_DATA'!$A$4:$A$1000=IFERROR(INDEX(DM_DON_VI!$B$4:$B$185,MATCH(O$4,DM_DON_VI!$D$4:$D$185,0)),""))*IFERROR(INDEX('01_PCTN_DATA'!$A$4:$ZZ$1000,0,MATCH($G10,'01_PCTN_DATA'!$A$3:$ZZ$3,0)),0))} -> 0 | P10: {=SUMPRODUCT(('01_PCTN_DATA'!$A$4:$A$1000=IFERROR(INDEX(DM_DON_VI!$B$4:$B$185,MATCH(P$4,DM_DON_VI!$D$4:$D$185,0)),""))*IFERROR(INDEX('01_PCTN_DATA'!$A$4:$ZZ$1000,0,MATCH($G10,'01_PCTN_DATA'!$A$3:$ZZ$3,0)),0))} -> 0 | Q10: {=SUMPRODUCT(('01_PCTN_DATA'!$A$4:$A$1000=IFERROR(INDEX(DM_DON_VI!$B$4:$B$185,MATCH(Q$4,DM_DON_VI!$D$4:$D$185,0)),""))*IFERROR(INDEX('01_PCTN_DATA'!$A$4:$ZZ$1000,0,MATCH($G10,'01_PCTN_DATA'!$A$3:$ZZ$3,0)),0))} -> 0 | R10: {=SUMPRODUCT(('01_PCTN_DATA'!$A$4:$A$1000=IFERROR(INDEX(DM_DON_VI!$B$4:$B$185,MATCH(R$4,DM_DON_VI!$D$4:$D$185,0)),""))*IFERROR(INDEX('01_PCTN_DATA'!$A$4:$ZZ$1000,0,MATCH($G10,'01_PCTN_DATA'!$A$3:$ZZ$3,0)),0))} -> 0 | S10: {=SUMPRODUCT(('01_PCTN_DATA'!$A$4:$A$1000=IFERROR(INDEX(DM_DON_VI!$B$4:$B$185,MATCH(S$4,DM_DON_VI!$D$4:$D$185,0)),""))*IFERROR(INDEX('01_PCTN_DATA'!$A$4:$ZZ$1000,0,MATCH($G10,'01_PCTN_DATA'!$A$3:$ZZ$3,0)),0))} -> 0 | ... GK10: {=SUMPRODUCT(('01_PCTN_DATA'!$A$4:$A$1000=IFERROR(INDEX(DM_DON_VI!$B$4:$B$185,MATCH(GK$4,DM_DON_VI!$D$4:$D$185,0)),""))*IFERROR(INDEX('01_PCTN_DATA'!$A$4:$ZZ$1000,0,MATCH($G10,'01_PCTN_DATA'!$A$3:$ZZ$3,0)),0))} -> 0
A11: 5 | B11: 5 | C11: Số lượt cán bộ, công chức, viên chức, nhân dân tham gia các lớp tập huấn, quán triệt pháp luật về phòng, chống tham nhũng, tiêu cực | D11: Lượt người | E11: {=SUMPRODUCT(IFERROR(INDEX('01_PCTN_DATA'!$A$4:$ZZ$1000,0,MATCH($G11,'01_PCTN_DATA'!$A$3:$ZZ$3,0)),0))} -> 0 | G11: P01_5 | H11: ITEM | I11: TUYÊN TRUYỀN, PHỔ BIẾN, GIÁO DỤC PHÁP LUẬT VỀ PHÒNG, CHỐNG THAM NHŨNG, TIÊU CỰC | K11: 5 | L11: {=SUMPRODUCT(('01_PCTN_DATA'!$A$4:$A$1000=IFERROR(INDEX(DM_DON_VI!$B$4:$B$185,MATCH(L$4,DM_DON_VI!$D$4:$D$185,0)),""))*IFERROR(INDEX('01_PCTN_DATA'!$A$4:$ZZ$1000,0,MATCH($G11,'01_PCTN_DATA'!$A$3:$ZZ$3,0)),0))} -> 0 | M11: {=SUMPRODUCT(('01_PCTN_DATA'!$A$4:$A$1000=IFERROR(INDEX(DM_DON_VI!$B$4:$B$185,MATCH(M$4,DM_DON_VI!$D$4:$D$185,0)),""))*IFERROR(INDEX('01_PCTN_DATA'!$A$4:$ZZ$1000,0,MATCH($G11,'01_PCTN_DATA'!$A$3:$ZZ$3,0)),0))} -> 0 | N11: {=SUMPRODUCT(('01_PCTN_DATA'!$A$4:$A$1000=IFERROR(INDEX(DM_DON_VI!$B$4:$B$185,MATCH(N$4,DM_DON_VI!$D$4:$D$185,0)),""))*IFERROR(INDEX('01_PCTN_DATA'!$A$4:$ZZ$1000,0,MATCH($G11,'01_PCTN_DATA'!$A$3:$ZZ$3,0)),0))} -> 0 | O11: {=SUMPRODUCT(('01_PCTN_DATA'!$A$4:$A$1000=IFERROR(INDEX(DM_DON_VI!$B$4:$B$185,MATCH(O$4,DM_DON_VI!$D$4:$D$185,0)),""))*IFERROR(INDEX('01_PCTN_DATA'!$A$4:$ZZ$1000,0,MATCH($G11,'01_PCTN_DATA'!$A$3:$ZZ$3,0)),0))} -> 0 | P11: {=SUMPRODUCT(('01_PCTN_DATA'!$A$4:$A$1000=IFERROR(INDEX(DM_DON_VI!$B$4:$B$185,MATCH(P$4,DM_DON_VI!$D$4:$D$185,0)),""))*IFERROR(INDEX('01_PCTN_DATA'!$A$4:$ZZ$1000,0,MATCH($G11,'01_PCTN_DATA'!$A$3:$ZZ$3,0)),0))} -> 0 | Q11: {=SUMPRODUCT(('01_PCTN_DATA'!$A$4:$A$1000=IFERROR(INDEX(DM_DON_VI!$B$4:$B$185,MATCH(Q$4,DM_DON_VI!$D$4:$D$185,0)),""))*IFERROR(INDEX('01_PCTN_DATA'!$A$4:$ZZ$1000,0,MATCH($G11,'01_PCTN_DATA'!$A$3:$ZZ$3,0)),0))} -> 0 | R11: {=SUMPRODUCT(('01_PCTN_DATA'!$A$4:$A$1000=IFERROR(INDEX(DM_DON_VI!$B$4:$B$185,MATCH(R$4,DM_DON_VI!$D$4:$D$185,0)),""))*IFERROR(INDEX('01_PCTN_DATA'!$A$4:$ZZ$1000,0,MATCH($G11,'01_PCTN_DATA'!$A$3:$ZZ$3,0)),0))} -> 0 | S11: {=SUMPRODUCT(('01_PCTN_DATA'!$A$4:$A$1000=IFERROR(INDEX(DM_DON_VI!$B$4:$B$185,MATCH(S$4,DM_DON_VI!$D$4:$D$185,0)),""))*IFERROR(INDEX('01_PCTN_DATA'!$A$4:$ZZ$1000,0,MATCH($G11,'01_PCTN_DATA'!$A$3:$ZZ$3,0)),0))} -> 0 | ... GK11: {=SUMPRODUCT(('01_PCTN_DATA'!$A$4:$A$1000=IFERROR(INDEX(DM_DON_VI!$B$4:$B$185,MATCH(GK$4,DM_DON_VI!$D$4:$D$185,0)),""))*IFERROR(INDEX('01_PCTN_DATA'!$A$4:$ZZ$1000,0,MATCH($G11,'01_PCTN_DATA'!$A$3:$ZZ$3,0)),0))} -> 0
A12: 6 | B12: 6 | C12: Số lượng đầu sách, tài liệu về pháp luật phòng, chống tham nhũng được xuất bản | D12: Tài liệu | E12: {=SUMPRODUCT(IFERROR(INDEX('01_PCTN_DATA'!$A$4:$ZZ$1000,0,MATCH($G12,'01_PCTN_DATA'!$A$3:$ZZ$3,0)),0))} -> 0 | G12: P01_6 | H12: ITEM | I12: TUYÊN TRUYỀN, PHỔ BIẾN, GIÁO DỤC PHÁP LUẬT VỀ PHÒNG, CHỐNG THAM NHŨNG, TIÊU CỰC | K12: 6 | L12: {=SUMPRODUCT(('01_PCTN_DATA'!$A$4:$A$1000=IFERROR(INDEX(DM_DON_VI!$B$4:$B$185,MATCH(L$4,DM_DON_VI!$D$4:$D$185,0)),""))*IFERROR(INDEX('01_PCTN_DATA'!$A$4:$ZZ$1000,0,MATCH($G12,'01_PCTN_DATA'!$A$3:$ZZ$3,0)),0))} -> 0 | M12: {=SUMPRODUCT(('01_PCTN_DATA'!$A$4:$A$1000=IFERROR(INDEX(DM_DON_VI!$B$4:$B$185,MATCH(M$4,DM_DON_VI!$D$4:$D$185,0)),""))*IFERROR(INDEX('01_PCTN_DATA'!$A$4:$ZZ$1000,0,MATCH($G12,'01_PCTN_DATA'!$A$3:$ZZ$3,0)),0))} -> 0 | N12: {=SUMPRODUCT(('01_PCTN_DATA'!$A$4:$A$1000=IFERROR(INDEX(DM_DON_VI!$B$4:$B$185,MATCH(N$4,DM_DON_VI!$D$4:$D$185,0)),""))*IFERROR(INDEX('01_PCTN_DATA'!$A$4:$ZZ$1000,0,MATCH($G12,'01_PCTN_DATA'!$A$3:$ZZ$3,0)),0))} -> 0 | O12: {=SUMPRODUCT(('01_PCTN_DATA'!$A$4:$A$1000=IFERROR(INDEX(DM_DON_VI!$B$4:$B$185,MATCH(O$4,DM_DON_VI!$D$4:$D$185,0)),""))*IFERROR(INDEX('01_PCTN_DATA'!$A$4:$ZZ$1000,0,MATCH($G12,'01_PCTN_DATA'!$A$3:$ZZ$3,0)),0))} -> 0 | P12: {=SUMPRODUCT(('01_PCTN_DATA'!$A$4:$A$1000=IFERROR(INDEX(DM_DON_VI!$B$4:$B$185,MATCH(P$4,DM_DON_VI!$D$4:$D$185,0)),""))*IFERROR(INDEX('01_PCTN_DATA'!$A$4:$ZZ$1000,0,MATCH($G12,'01_PCTN_DATA'!$A$3:$ZZ$3,0)),0))} -> 0 | Q12: {=SUMPRODUCT(('01_PCTN_DATA'!$A$4:$A$1000=IFERROR(INDEX(DM_DON_VI!$B$4:$B$185,MATCH(Q$4,DM_DON_VI!$D$4:$D$185,0)),""))*IFERROR(INDEX('01_PCTN_DATA'!$A$4:$ZZ$1000,0,MATCH($G12,'01_PCTN_DATA'!$A$3:$ZZ$3,0)),0))} -> 0 | R12: {=SUMPRODUCT(('01_PCTN_DATA'!$A$4:$A$1000=IFERROR(INDEX(DM_DON_VI!$B$4:$B$185,MATCH(R$4,DM_DON_VI!$D$4:$D$185,0)),""))*IFERROR(INDEX('01_PCTN_DATA'!$A$4:$ZZ$1000,0,MATCH($G12,'01_PCTN_DATA'!$A$3:$ZZ$3,0)),0))} -> 0 | S12: {=SUMPRODUCT(('01_PCTN_DATA'!$A$4:$A$1000=IFERROR(INDEX(DM_DON_VI!$B$4:$B$185,MATCH(S$4,DM_DON_VI!$D$4:$D$185,0)),""))*IFERROR(INDEX('01_PCTN_DATA'!$A$4:$ZZ$1000,0,MATCH($G12,'01_PCTN_DATA'!$A$3:$ZZ$3,0)),0))} -> 0 | ... GK12: {=SUMPRODUCT(('01_PCTN_DATA'!$A$4:$A$1000=IFERROR(INDEX(DM_DON_VI!$B$4:$B$185,MATCH(GK$4,DM_DON_VI!$D$4:$D$185,0)),""))*IFERROR(INDEX('01_PCTN_DATA'!$A$4:$ZZ$1000,0,MATCH($G12,'01_PCTN_DATA'!$A$3:$ZZ$3,0)),0))} -> 0
A13: THANH TRA TRÁCH NHIỆM THỰC HIỆN PHÁP LUẬT VỀ PHÒNG, CHỐNG TNLPTC | H13: SECTION | I13: THANH TRA TRÁCH NHIỆM THỰC HIỆN PHÁP LUẬT VỀ PHÒNG, CHỐNG TNLPTC
A14: 7 | B14: 7 | C14: Tổng số cuộc thanh tra trách nhiệm thực hiện pháp luật về phòng, chống TNLPTC | D14: Cuộc | E14: {=SUMPRODUCT(IFERROR(INDEX('01_PCTN_DATA'!$A$4:$ZZ$1000,0,MATCH($G14,'01_PCTN_DATA'!$A$3:$ZZ$3,0)),0))} -> 0 | G14: P01_7 | H14: ITEM | I14: THANH TRA TRÁCH NHIỆM THỰC HIỆN PHÁP LUẬT VỀ PHÒNG, CHỐNG TNLPTC | K14: 7 | L14: {=SUMPRODUCT(('01_PCTN_DATA'!$A$4:$A$1000=IFERROR(INDEX(DM_DON_VI!$B$4:$B$185,MATCH(L$4,DM_DON_VI!$D$4:$D$185,0)),""))*IFERROR(INDEX('01_PCTN_DATA'!$A$4:$ZZ$1000,0,MATCH($G14,'01_PCTN_DATA'!$A$3:$ZZ$3,0)),0))} -> 0 | M14: {=SUMPRODUCT(('01_PCTN_DATA'!$A$4:$A$1000=IFERROR(INDEX(DM_DON_VI!$B$4:$B$185,MATCH(M$4,DM_DON_VI!$D$4:$D$185,0)),""))*IFERROR(INDEX('01_PCTN_DATA'!$A$4:$ZZ$1000,0,MATCH($G14,'01_PCTN_DATA'!$A$3:$ZZ$3,0)),0))} -> 0 | N14: {=SUMPRODUCT(('01_PCTN_DATA'!$A$4:$A$1000=IFERROR(INDEX(DM_DON_VI!$B$4:$B$185,MATCH(N$4,DM_DON_VI!$D$4:$D$185,0)),""))*IFERROR(INDEX('01_PCTN_DATA'!$A$4:$ZZ$1000,0,MATCH($G14,'01_PCTN_DATA'!$A$3:$ZZ$3,0)),0))} -> 0 | O14: {=SUMPRODUCT(('01_PCTN_DATA'!$A$4:$A$1000=IFERROR(INDEX(DM_DON_VI!$B$4:$B$185,MATCH(O$4,DM_DON_VI!$D$4:$D$185,0)),""))*IFERROR(INDEX('01_PCTN_DATA'!$A$4:$ZZ$1000,0,MATCH($G14,'01_PCTN_DATA'!$A$3:$ZZ$3,0)),0))} -> 0 | P14: {=SUMPRODUCT(('01_PCTN_DATA'!$A$4:$A$1000=IFERROR(INDEX(DM_DON_VI!$B$4:$B$185,MATCH(P$4,DM_DON_VI!$D$4:$D$185,0)),""))*IFERROR(INDEX('01_PCTN_DATA'!$A$4:$ZZ$1000,0,MATCH($G14,'01_PCTN_DATA'!$A$3:$ZZ$3,0)),0))} -> 0 | Q14: {=SUMPRODUCT(('01_PCTN_DATA'!$A$4:$A$1000=IFERROR(INDEX(DM_DON_VI!$B$4:$B$185,MATCH(Q$4,DM_DON_VI!$D$4:$D$185,0)),""))*IFERROR(INDEX('01_PCTN_DATA'!$A$4:$ZZ$1000,0,MATCH($G14,'01_PCTN_DATA'!$A$3:$ZZ$3,0)),0))} -> 0 | R14: {=SUMPRODUCT(('01_PCTN_DATA'!$A$4:$A$1000=IFERROR(INDEX(DM_DON_VI!$B$4:$B$185,MATCH(R$4,DM_DON_VI!$D$4:$D$185,0)),""))*IFERROR(INDEX('01_PCTN_DATA'!$A$4:$ZZ$1000,0,MATCH($G14,'01_PCTN_DATA'!$A$3:$ZZ$3,0)),0))} -> 0 | S14: {=SUMPRODUCT(('01_PCTN_DATA'!$A$4:$A$1000=IFERROR(INDEX(DM_DON_VI!$B$4:$B$185,MATCH(S$4,DM_DON_VI!$D$4:$D$185,0)),""))*IFERROR(INDEX('01_PCTN_DATA'!$A$4:$ZZ$1000,0,MATCH($G14,'01_PCTN_DATA'!$A$3:$ZZ$3,0)),0))} -> 0 | ... GK14: {=SUMPRODUCT(('01_PCTN_DATA'!$A$4:$A$1000=IFERROR(INDEX(DM_DON_VI!$B$4:$B$185,MATCH(GK$4,DM_DON_VI!$D$4:$D$185,0)),""))*IFERROR(INDEX('01_PCTN_DATA'!$A$4:$ZZ$1000,0,MATCH($G14,'01_PCTN_DATA'!$A$3:$ZZ$3,0)),0))} -> 0
A15: 8 | B15: 8 | C15: Số cuộc thanh tra trách nhiệm thực hiện pháp luật về phòng, chống TNLPTC đã ban hành kết luận | D15: Cuộc | E15: {=SUMPRODUCT(IFERROR(INDEX('01_PCTN_DATA'!$A$4:$ZZ$1000,0,MATCH($G15,'01_PCTN_DATA'!$A$3:$ZZ$3,0)),0))} -> 0 | G15: P01_8 | H15: ITEM | I15: THANH TRA TRÁCH NHIỆM THỰC HIỆN PHÁP LUẬT VỀ PHÒNG, CHỐNG TNLPTC | K15: 8 | L15: {=SUMPRODUCT(('01_PCTN_DATA'!$A$4:$A$1000=IFERROR(INDEX(DM_DON_VI!$B$4:$B$185,MATCH(L$4,DM_DON_VI!$D$4:$D$185,0)),""))*IFERROR(INDEX('01_PCTN_DATA'!$A$4:$ZZ$1000,0,MATCH($G15,'01_PCTN_DATA'!$A$3:$ZZ$3,0)),0))} -> 0 | M15: {=SUMPRODUCT(('01_PCTN_DATA'!$A$4:$A$1000=IFERROR(INDEX(DM_DON_VI!$B$4:$B$185,MATCH(M$4,DM_DON_VI!$D$4:$D$185,0)),""))*IFERROR(INDEX('01_PCTN_DATA'!$A$4:$ZZ$1000,0,MATCH($G15,'01_PCTN_DATA'!$A$3:$ZZ$3,0)),0))} -> 0 | N15: {=SUMPRODUCT(('01_PCTN_DATA'!$A$4:$A$1000=IFERROR(INDEX(DM_DON_VI!$B$4:$B$185,MATCH(N$4,DM_DON_VI!$D$4:$D$185,0)),""))*IFERROR(INDEX('01_PCTN_DATA'!$A$4:$ZZ$1000,0,MATCH($G15,'01_PCTN_DATA'!$A$3:$ZZ$3,0)),0))} -> 0 | O15: {=SUMPRODUCT(('01_PCTN_DATA'!$A$4:$A$1000=IFERROR(INDEX(DM_DON_VI!$B$4:$B$185,MATCH(O$4,DM_DON_VI!$D$4:$D$185,0)),""))*IFERROR(INDEX('01_PCTN_DATA'!$A$4:$ZZ$1000,0,MATCH($G15,'01_PCTN_DATA'!$A$3:$ZZ$3,0)),0))} -> 0 | P15: {=SUMPRODUCT(('01_PCTN_DATA'!$A$4:$A$1000=IFERROR(INDEX(DM_DON_VI!$B$4:$B$185,MATCH(P$4,DM_DON_VI!$D$4:$D$185,0)),""))*IFERROR(INDEX('01_PCTN_DATA'!$A$4:$ZZ$1000,0,MATCH($G15,'01_PCTN_DATA'!$A$3:$ZZ$3,0)),0))} -> 0 | Q15: {=SUMPRODUCT(('01_PCTN_DATA'!$A$4:$A$1000=IFERROR(INDEX(DM_DON_VI!$B$4:$B$185,MATCH(Q$4,DM_DON_VI!$D$4:$D$185,0)),""))*IFERROR(INDEX('01_PCTN_DATA'!$A$4:$ZZ$1000,0,MATCH($G15,'01_PCTN_DATA'!$A$3:$ZZ$3,0)),0))} -> 0 | R15: {=SUMPRODUCT(('01_PCTN_DATA'!$A$4:$A$1000=IFERROR(INDEX(DM_DON_VI!$B$4:$B$185,MATCH(R$4,DM_DON_VI!$D$4:$D$185,0)),""))*IFERROR(INDEX('01_PCTN_DATA'!$A$4:$ZZ$1000,0,MATCH($G15,'01_PCTN_DATA'!$A$3:$ZZ$3,0)),0))} -> 0 | S15: {=SUMPRODUCT(('01_PCTN_DATA'!$A$4:$A$1000=IFERROR(INDEX(DM_DON_VI!$B$4:$B$185,MATCH(S$4,DM_DON_VI!$D$4:$D$185,0)),""))*IFERROR(INDEX('01_PCTN_DATA'!$A$4:$ZZ$1000,0,MATCH($G15,'01_PCTN_DATA'!$A$3:$ZZ$3,0)),0))} -> 0 | ... GK15: {=SUMPRODUCT(('01_PCTN_DATA'!$A$4:$A$1000=IFERROR(INDEX(DM_DON_VI!$B$4:$B$185,MATCH(GK$4,DM_DON_VI!$D$4:$D$185,0)),""))*IFERROR(INDEX('01_PCTN_DATA'!$A$4:$ZZ$1000,0,MATCH($G15,'01_PCTN_DATA'!$A$3:$ZZ$3,0)),0))} -> 0
A16: 9 | B16: 9 | C16: Số đơn vị được thanh tra | D16: Đơn vị | E16: {=SUMPRODUCT(IFERROR(INDEX('01_PCTN_DATA'!$A$4:$ZZ$1000,0,MATCH($G16,'01_PCTN_DATA'!$A$3:$ZZ$3,0)),0))} -> 0 | G16: P01_9 | H16: ITEM | I16: THANH TRA TRÁCH NHIỆM THỰC HIỆN PHÁP LUẬT VỀ PHÒNG, CHỐNG TNLPTC | K16: 9 | L16: {=SUMPRODUCT(('01_PCTN_DATA'!$A$4:$A$1000=IFERROR(INDEX(DM_DON_VI!$B$4:$B$185,MATCH(L$4,DM_DON_VI!$D$4:$D$185,0)),""))*IFERROR(INDEX('01_PCTN_DATA'!$A$4:$ZZ$1000,0,MATCH($G16,'01_PCTN_DATA'!$A$3:$ZZ$3,0)),0))} -> 0 | M16: {=SUMPRODUCT(('01_PCTN_DATA'!$A$4:$A$1000=IFERROR(INDEX(DM_DON_VI!$B$4:$B$185,MATCH(M$4,DM_DON_VI!$D$4:$D$185,0)),""))*IFERROR(INDEX('01_PCTN_DATA'!$A$4:$ZZ$1000,0,MATCH($G16,'01_PCTN_DATA'!$A$3:$ZZ$3,0)),0))} -> 0 | N16: {=SUMPRODUCT(('01_PCTN_DATA'!$A$4:$A$1000=IFERROR(INDEX(DM_DON_VI!$B$4:$B$185,MATCH(N$4,DM_DON_VI!$D$4:$D$185,0)),""))*IFERROR(INDEX('01_PCTN_DATA'!$A$4:$ZZ$1000,0,MATCH($G16,'01_PCTN_DATA'!$A$3:$ZZ$3,0)),0))} -> 0 | O16: {=SUMPRODUCT(('01_PCTN_DATA'!$A$4:$A$1000=IFERROR(INDEX(DM_DON_VI!$B$4:$B$185,MATCH(O$4,DM_DON_VI!$D$4:$D$185,0)),""))*IFERROR(INDEX('01_PCTN_DATA'!$A$4:$ZZ$1000,0,MATCH($G16,'01_PCTN_DATA'!$A$3:$ZZ$3,0)),0))} -> 0 | P16: {=SUMPRODUCT(('01_PCTN_DATA'!$A$4:$A$1000=IFERROR(INDEX(DM_DON_VI!$B$4:$B$185,MATCH(P$4,DM_DON_VI!$D$4:$D$185,0)),""))*IFERROR(INDEX('01_PCTN_DATA'!$A$4:$ZZ$1000,0,MATCH($G16,'01_PCTN_DATA'!$A$3:$ZZ$3,0)),0))} -> 0 | Q16: {=SUMPRODUCT(('01_PCTN_DATA'!$A$4:$A$1000=IFERROR(INDEX(DM_DON_VI!$B$4:$B$185,MATCH(Q$4,DM_DON_VI!$D$4:$D$185,0)),""))*IFERROR(INDEX('01_PCTN_DATA'!$A$4:$ZZ$1000,0,MATCH($G16,'01_PCTN_DATA'!$A$3:$ZZ$3,0)),0))} -> 0 | R16: {=SUMPRODUCT(('01_PCTN_DATA'!$A$4:$A$1000=IFERROR(INDEX(DM_DON_VI!$B$4:$B$185,MATCH(R$4,DM_DON_VI!$D$4:$D$185,0)),""))*IFERROR(INDEX('01_PCTN_DATA'!$A$4:$ZZ$1000,0,MATCH($G16,'01_PCTN_DATA'!$A$3:$ZZ$3,0)),0))} -> 0 | S16: {=SUMPRODUCT(('01_PCTN_DATA'!$A$4:$A$1000=IFERROR(INDEX(DM_DON_VI!$B$4:$B$185,MATCH(S$4,DM_DON_VI!$D$4:$D$185,0)),""))*IFERROR(INDEX('01_PCTN_DATA'!$A$4:$ZZ$1000,0,MATCH($G16,'01_PCTN_DATA'!$A$3:$ZZ$3,0)),0))} -> 0 | ... GK16: {=SUMPRODUCT(('01_PCTN_DATA'!$A$4:$A$1000=IFERROR(INDEX(DM_DON_VI!$B$4:$B$185,MATCH(GK$4,DM_DON_VI!$D$4:$D$185,0)),""))*IFERROR(INDEX('01_PCTN_DATA'!$A$4:$ZZ$1000,0,MATCH($G16,'01_PCTN_DATA'!$A$3:$ZZ$3,0)),0))} -> 0
C17: Kiến nghị xử lý hành chính | H17: SUBSECTION | I17: THANH TRA TRÁCH NHIỆM THỰC HIỆN PHÁP LUẬT VỀ PHÒNG, CHỐNG TNLPTC | J17: Kiến nghị xử lý hành chính
A18: 10 | B18: 10 | C18: + Tập thể | D18: Tập thể | E18: {=SUMPRODUCT(IFERROR(INDEX('01_PCTN_DATA'!$A$4:$ZZ$1000,0,MATCH($G18,'01_PCTN_DATA'!$A$3:$ZZ$3,0)),0))} -> 0 | G18: P01_10 | H18: ITEM | I18: THANH TRA TRÁCH NHIỆM THỰC HIỆN PHÁP LUẬT VỀ PHÒNG, CHỐNG TNLPTC | J18: Kiến nghị xử lý hành chính | K18: 10 | L18: {=SUMPRODUCT(('01_PCTN_DATA'!$A$4:$A$1000=IFERROR(INDEX(DM_DON_VI!$B$4:$B$185,MATCH(L$4,DM_DON_VI!$D$4:$D$185,0)),""))*IFERROR(INDEX('01_PCTN_DATA'!$A$4:$ZZ$1000,0,MATCH($G18,'01_PCTN_DATA'!$A$3:$ZZ$3,0)),0))} -> 0 | M18: {=SUMPRODUCT(('01_PCTN_DATA'!$A$4:$A$1000=IFERROR(INDEX(DM_DON_VI!$B$4:$B$185,MATCH(M$4,DM_DON_VI!$D$4:$D$185,0)),""))*IFERROR(INDEX('01_PCTN_DATA'!$A$4:$ZZ$1000,0,MATCH($G18,'01_PCTN_DATA'!$A$3:$ZZ$3,0)),0))} -> 0 | N18: {=SUMPRODUCT(('01_PCTN_DATA'!$A$4:$A$1000=IFERROR(INDEX(DM_DON_VI!$B$4:$B$185,MATCH(N$4,DM_DON_VI!$D$4:$D$185,0)),""))*IFERROR(INDEX('01_PCTN_DATA'!$A$4:$ZZ$1000,0,MATCH($G18,'01_PCTN_DATA'!$A$3:$ZZ$3,0)),0))} -> 0 | O18: {=SUMPRODUCT(('01_PCTN_DATA'!$A$4:$A$1000=IFERROR(INDEX(DM_DON_VI!$B$4:$B$185,MATCH(O$4,DM_DON_VI!$D$4:$D$185,0)),""))*IFERROR(INDEX('01_PCTN_DATA'!$A$4:$ZZ$1000,0,MATCH($G18,'01_PCTN_DATA'!$A$3:$ZZ$3,0)),0))} -> 0 | P18: {=SUMPRODUCT(('01_PCTN_DATA'!$A$4:$A$1000=IFERROR(INDEX(DM_DON_VI!$B$4:$B$185,MATCH(P$4,DM_DON_VI!$D$4:$D$185,0)),""))*IFERROR(INDEX('01_PCTN_DATA'!$A$4:$ZZ$1000,0,MATCH($G18,'01_PCTN_DATA'!$A$3:$ZZ$3,0)),0))} -> 0 | Q18: {=SUMPRODUCT(('01_PCTN_DATA'!$A$4:$A$1000=IFERROR(INDEX(DM_DON_VI!$B$4:$B$185,MATCH(Q$4,DM_DON_VI!$D$4:$D$185,0)),""))*IFERROR(INDEX('01_PCTN_DATA'!$A$4:$ZZ$1000,0,MATCH($G18,'01_PCTN_DATA'!$A$3:$ZZ$3,0)),0))} -> 0 | R18: {=SUMPRODUCT(('01_PCTN_DATA'!$A$4:$A$1000=IFERROR(INDEX(DM_DON_VI!$B$4:$B$185,MATCH(R$4,DM_DON_VI!$D$4:$D$185,0)),""))*IFERROR(INDEX('01_PCTN_DATA'!$A$4:$ZZ$1000,0,MATCH($G18,'01_PCTN_DATA'!$A$3:$ZZ$3,0)),0))} -> 0 | S18: {=SUMPRODUCT(('01_PCTN_DATA'!$A$4:$A$1000=IFERROR(INDEX(DM_DON_VI!$B$4:$B$185,MATCH(S$4,DM_DON_VI!$D$4:$D$185,0)),""))*IFERROR(INDEX('01_PCTN_DATA'!$A$4:$ZZ$1000,0,MATCH($G18,'01_PCTN_DATA'!$A$3:$ZZ$3,0)),0))} -> 0 | ... GK18: {=SUMPRODUCT(('01_PCTN_DATA'!$A$4:$A$1000=IFERROR(INDEX(DM_DON_VI!$B$4:$B$185,MATCH(GK$4,DM_DON_VI!$D$4:$D$185,0)),""))*IFERROR(INDEX('01_PCTN_DATA'!$A$4:$ZZ$1000,0,MATCH($G18,'01_PCTN_DATA'!$A$3:$ZZ$3,0)),0))} -> 0
A19: 11 | B19: 11 | C19: + Cá nhân | D19: Người | E19: {=SUMPRODUCT(IFERROR(INDEX('01_PCTN_DATA'!$A$4:$ZZ$1000,0,MATCH($G19,'01_PCTN_DATA'!$A$3:$ZZ$3,0)),0))} -> 0 | G19: P01_11 | H19: ITEM | I19: THANH TRA TRÁCH NHIỆM THỰC HIỆN PHÁP LUẬT VỀ PHÒNG, CHỐNG TNLPTC | J19: Kiến nghị xử lý hành chính | K19: 11 | L19: {=SUMPRODUCT(('01_PCTN_DATA'!$A$4:$A$1000=IFERROR(INDEX(DM_DON_VI!$B$4:$B$185,MATCH(L$4,DM_DON_VI!$D$4:$D$185,0)),""))*IFERROR(INDEX('01_PCTN_DATA'!$A$4:$ZZ$1000,0,MATCH($G19,'01_PCTN_DATA'!$A$3:$ZZ$3,0)),0))} -> 0 | M19: {=SUMPRODUCT(('01_PCTN_DATA'!$A$4:$A$1000=IFERROR(INDEX(DM_DON_VI!$B$4:$B$185,MATCH(M$4,DM_DON_VI!$D$4:$D$185,0)),""))*IFERROR(INDEX('01_PCTN_DATA'!$A$4:$ZZ$1000,0,MATCH($G19,'01_PCTN_DATA'!$A$3:$ZZ$3,0)),0))} -> 0 | N19: {=SUMPRODUCT(('01_PCTN_DATA'!$A$4:$A$1000=IFERROR(INDEX(DM_DON_VI!$B$4:$B$185,MATCH(N$4,DM_DON_VI!$D$4:$D$185,0)),""))*IFERROR(INDEX('01_PCTN_DATA'!$A$4:$ZZ$1000,0,MATCH($G19,'01_PCTN_DATA'!$A$3:$ZZ$3,0)),0))} -> 0 | O19: {=SUMPRODUCT(('01_PCTN_DATA'!$A$4:$A$1000=IFERROR(INDEX(DM_DON_VI!$B$4:$B$185,MATCH(O$4,DM_DON_VI!$D$4:$D$185,0)),""))*IFERROR(INDEX('01_PCTN_DATA'!$A$4:$ZZ$1000,0,MATCH($G19,'01_PCTN_DATA'!$A$3:$ZZ$3,0)),0))} -> 0 | P19: {=SUMPRODUCT(('01_PCTN_DATA'!$A$4:$A$1000=IFERROR(INDEX(DM_DON_VI!$B$4:$B$185,MATCH(P$4,DM_DON_VI!$D$4:$D$185,0)),""))*IFERROR(INDEX('01_PCTN_DATA'!$A$4:$ZZ$1000,0,MATCH($G19,'01_PCTN_DATA'!$A$3:$ZZ$3,0)),0))} -> 0 | Q19: {=SUMPRODUCT(('01_PCTN_DATA'!$A$4:$A$1000=IFERROR(INDEX(DM_DON_VI!$B$4:$B$185,MATCH(Q$4,DM_DON_VI!$D$4:$D$185,0)),""))*IFERROR(INDEX('01_PCTN_DATA'!$A$4:$ZZ$1000,0,MATCH($G19,'01_PCTN_DATA'!$A$3:$ZZ$3,0)),0))} -> 0 | R19: {=SUMPRODUCT(('01_PCTN_DATA'!$A$4:$A$1000=IFERROR(INDEX(DM_DON_VI!$B$4:$B$185,MATCH(R$4,DM_DON_VI!$D$4:$D$185,0)),""))*IFERROR(INDEX('01_PCTN_DATA'!$A$4:$ZZ$1000,0,MATCH($G19,'01_PCTN_DATA'!$A$3:$ZZ$3,0)),0))} -> 0 | S19: {=SUMPRODUCT(('01_PCTN_DATA'!$A$4:$A$1000=IFERROR(INDEX(DM_DON_VI!$B$4:$B$185,MATCH(S$4,DM_DON_VI!$D$4:$D$185,0)),""))*IFERROR(INDEX('01_PCTN_DATA'!$A$4:$ZZ$1000,0,MATCH($G19,'01_PCTN_DATA'!$A$3:$ZZ$3,0)),0))} -> 0 | ... GK19: {=SUMPRODUCT(('01_PCTN_DATA'!$A$4:$A$1000=IFERROR(INDEX(DM_DON_VI!$B$4:$B$185,MATCH(GK$4,DM_DON_VI!$D$4:$D$185,0)),""))*IFERROR(INDEX('01_PCTN_DATA'!$A$4:$ZZ$1000,0,MATCH($G19,'01_PCTN_DATA'!$A$3:$ZZ$3,0)),0))} -> 0
C20: Kiến nghị xử lý hình sự | H20: SUBSECTION | I20: THANH TRA TRÁCH NHIỆM THỰC HIỆN PHÁP LUẬT VỀ PHÒNG, CHỐNG TNLPTC | J20: Kiến nghị xử lý hình sự
A21: 12 | B21: 12 | C21: + Số vụ | D21: Vụ | E21: {=SUMPRODUCT(IFERROR(INDEX('01_PCTN_DATA'!$A$4:$ZZ$1000,0,MATCH($G21,'01_PCTN_DATA'!$A$3:$ZZ$3,0)),0))} -> 0 | G21: P01_12 | H21: ITEM | I21: THANH TRA TRÁCH NHIỆM THỰC HIỆN PHÁP LUẬT VỀ PHÒNG, CHỐNG TNLPTC | J21: Kiến nghị xử lý hình sự | K21: 12 | L21: {=SUMPRODUCT(('01_PCTN_DATA'!$A$4:$A$1000=IFERROR(INDEX(DM_DON_VI!$B$4:$B$185,MATCH(L$4,DM_DON_VI!$D$4:$D$185,0)),""))*IFERROR(INDEX('01_PCTN_DATA'!$A$4:$ZZ$1000,0,MATCH($G21,'01_PCTN_DATA'!$A$3:$ZZ$3,0)),0))} -> 0 | M21: {=SUMPRODUCT(('01_PCTN_DATA'!$A$4:$A$1000=IFERROR(INDEX(DM_DON_VI!$B$4:$B$185,MATCH(M$4,DM_DON_VI!$D$4:$D$185,0)),""))*IFERROR(INDEX('01_PCTN_DATA'!$A$4:$ZZ$1000,0,MATCH($G21,'01_PCTN_DATA'!$A$3:$ZZ$3,0)),0))} -> 0 | N21: {=SUMPRODUCT(('01_PCTN_DATA'!$A$4:$A$1000=IFERROR(INDEX(DM_DON_VI!$B$4:$B$185,MATCH(N$4,DM_DON_VI!$D$4:$D$185,0)),""))*IFERROR(INDEX('01_PCTN_DATA'!$A$4:$ZZ$1000,0,MATCH($G21,'01_PCTN_DATA'!$A$3:$ZZ$3,0)),0))} -> 0 | O21: {=SUMPRODUCT(('01_PCTN_DATA'!$A$4:$A$1000=IFERROR(INDEX(DM_DON_VI!$B$4:$B$185,MATCH(O$4,DM_DON_VI!$D$4:$D$185,0)),""))*IFERROR(INDEX('01_PCTN_DATA'!$A$4:$ZZ$1000,0,MATCH($G21,'01_PCTN_DATA'!$A$3:$ZZ$3,0)),0))} -> 0 | P21: {=SUMPRODUCT(('01_PCTN_DATA'!$A$4:$A$1000=IFERROR(INDEX(DM_DON_VI!$B$4:$B$185,MATCH(P$4,DM_DON_VI!$D$4:$D$185,0)),""))*IFERROR(INDEX('01_PCTN_DATA'!$A$4:$ZZ$1000,0,MATCH($G21,'01_PCTN_DATA'!$A$3:$ZZ$3,0)),0))} -> 0 | Q21: {=SUMPRODUCT(('01_PCTN_DATA'!$A$4:$A$1000=IFERROR(INDEX(DM_DON_VI!$B$4:$B$185,MATCH(Q$4,DM_DON_VI!$D$4:$D$185,0)),""))*IFERROR(INDEX('01_PCTN_DATA'!$A$4:$ZZ$1000,0,MATCH($G21,'01_PCTN_DATA'!$A$3:$ZZ$3,0)),0))} -> 0 | R21: {=SUMPRODUCT(('01_PCTN_DATA'!$A$4:$A$1000=IFERROR(INDEX(DM_DON_VI!$B$4:$B$185,MATCH(R$4,DM_DON_VI!$D$4:$D$185,0)),""))*IFERROR(INDEX('01_PCTN_DATA'!$A$4:$ZZ$1000,0,MATCH($G21,'01_PCTN_DATA'!$A$3:$ZZ$3,0)),0))} -> 0 | S21: {=SUMPRODUCT(('01_PCTN_DATA'!$A$4:$A$1000=IFERROR(INDEX(DM_DON_VI!$B$4:$B$185,MATCH(S$4,DM_DON_VI!$D$4:$D$185,0)),""))*IFERROR(INDEX('01_PCTN_DATA'!$A$4:$ZZ$1000,0,MATCH($G21,'01_PCTN_DATA'!$A$3:$ZZ$3,0)),0))} -> 0 | ... GK21: {=SUMPRODUCT(('01_PCTN_DATA'!$A$4:$A$1000=IFERROR(INDEX(DM_DON_VI!$B$4:$B$185,MATCH(GK$4,DM_DON_VI!$D$4:$D$185,0)),""))*IFERROR(INDEX('01_PCTN_DATA'!$A$4:$ZZ$1000,0,MATCH($G21,'01_PCTN_DATA'!$A$3:$ZZ$3,0)),0))} -> 0
A22: 13 | B22: 13 | C22: + Số đối tượng | D22: Đối tượng | E22: {=SUMPRODUCT(IFERROR(INDEX('01_PCTN_DATA'!$A$4:$ZZ$1000,0,MATCH($G22,'01_PCTN_DATA'!$A$3:$ZZ$3,0)),0))} -> 0 | G22: P01_13 | H22: ITEM | I22: THANH TRA TRÁCH NHIỆM THỰC HIỆN PHÁP LUẬT VỀ PHÒNG, CHỐNG TNLPTC | J22: Kiến nghị xử lý hình sự | K22: 13 | L22: {=SUMPRODUCT(('01_PCTN_DATA'!$A$4:$A$1000=IFERROR(INDEX(DM_DON_VI!$B$4:$B$185,MATCH(L$4,DM_DON_VI!$D$4:$D$185,0)),""))*IFERROR(INDEX('01_PCTN_DATA'!$A$4:$ZZ$1000,0,MATCH($G22,'01_PCTN_DATA'!$A$3:$ZZ$3,0)),0))} -> 0 | M22: {=SUMPRODUCT(('01_PCTN_DATA'!$A$4:$A$1000=IFERROR(INDEX(DM_DON_VI!$B$4:$B$185,MATCH(M$4,DM_DON_VI!$D$4:$D$185,0)),""))*IFERROR(INDEX('01_PCTN_DATA'!$A$4:$ZZ$1000,0,MATCH($G22,'01_PCTN_DATA'!$A$3:$ZZ$3,0)),0))} -> 0 | N22: {=SUMPRODUCT(('01_PCTN_DATA'!$A$4:$A$1000=IFERROR(INDEX(DM_DON_VI!$B$4:$B$185,MATCH(N$4,DM_DON_VI!$D$4:$D$185,0)),""))*IFERROR(INDEX('01_PCTN_DATA'!$A$4:$ZZ$1000,0,MATCH($G22,'01_PCTN_DATA'!$A$3:$ZZ$3,0)),0))} -> 0 | O22: {=SUMPRODUCT(('01_PCTN_DATA'!$A$4:$A$1000=IFERROR(INDEX(DM_DON_VI!$B$4:$B$185,MATCH(O$4,DM_DON_VI!$D$4:$D$185,0)),""))*IFERROR(INDEX('01_PCTN_DATA'!$A$4:$ZZ$1000,0,MATCH($G22,'01_PCTN_DATA'!$A$3:$ZZ$3,0)),0))} -> 0 | P22: {=SUMPRODUCT(('01_PCTN_DATA'!$A$4:$A$1000=IFERROR(INDEX(DM_DON_VI!$B$4:$B$185,MATCH(P$4,DM_DON_VI!$D$4:$D$185,0)),""))*IFERROR(INDEX('01_PCTN_DATA'!$A$4:$ZZ$1000,0,MATCH($G22,'01_PCTN_DATA'!$A$3:$ZZ$3,0)),0))} -> 0 | Q22: {=SUMPRODUCT(('01_PCTN_DATA'!$A$4:$A$1000=IFERROR(INDEX(DM_DON_VI!$B$4:$B$185,MATCH(Q$4,DM_DON_VI!$D$4:$D$185,0)),""))*IFERROR(INDEX('01_PCTN_DATA'!$A$4:$ZZ$1000,0,MATCH($G22,'01_PCTN_DATA'!$A$3:$ZZ$3,0)),0))} -> 0 | R22: {=SUMPRODUCT(('01_PCTN_DATA'!$A$4:$A$1000=IFERROR(INDEX(DM_DON_VI!$B$4:$B$185,MATCH(R$4,DM_DON_VI!$D$4:$D$185,0)),""))*IFERROR(INDEX('01_PCTN_DATA'!$A$4:$ZZ$1000,0,MATCH($G22,'01_PCTN_DATA'!$A$3:$ZZ$3,0)),0))} -> 0 | S22: {=SUMPRODUCT(('01_PCTN_DATA'!$A$4:$A$1000=IFERROR(INDEX(DM_DON_VI!$B$4:$B$185,MATCH(S$4,DM_DON_VI!$D$4:$D$185,0)),""))*IFERROR(INDEX('01_PCTN_DATA'!$A$4:$ZZ$1000,0,MATCH($G22,'01_PCTN_DATA'!$A$3:$ZZ$3,0)),0))} -> 0 | ... GK22: {=SUMPRODUCT(('01_PCTN_DATA'!$A$4:$A$1000=IFERROR(INDEX(DM_DON_VI!$B$4:$B$185,MATCH(GK$4,DM_DON_VI!$D$4:$D$185,0)),""))*IFERROR(INDEX('01_PCTN_DATA'!$A$4:$ZZ$1000,0,MATCH($G22,'01_PCTN_DATA'!$A$3:$ZZ$3,0)),0))} -> 0
A23: PHÒNG NGỪA THAM NHŨNG TRONG CƠ QUAN, TỔ CHỨC, ĐƠN VỊ | H23: SECTION | I23: PHÒNG NGỪA THAM NHŨNG TRONG CƠ QUAN, TỔ CHỨC, ĐƠN VỊ
C24: Kết quả thực hiện công khai, minh bạch về tổ chức và hoạt động | H24: SUBSECTION | I24: PHÒNG NGỪA THAM NHŨNG TRONG CƠ QUAN, TỔ CHỨC, ĐƠN VỊ | J24: Kết quả thực hiện công khai, minh bạch về tổ chức và hoạt động
A25: 14 | B25: 14 | C25: Số cơ quan, tổ chức, đơn vị được kiểm tra việc thực hiện các quy định về công khai, minh bạch về tổ chức và hoạt động | D25: CQ, TC, ĐV | E25: {=SUMPRODUCT(IFERROR(INDEX('01_PCTN_DATA'!$A$4:$ZZ$1000,0,MATCH($G25,'01_PCTN_DATA'!$A$3:$ZZ$3,0)),0))} -> 0 | G25: P01_14 | H25: ITEM | I25: PHÒNG NGỪA THAM NHŨNG TRONG CƠ QUAN, TỔ CHỨC, ĐƠN VỊ | J25: Kết quả thực hiện công khai, minh bạch về tổ chức và hoạt động | K25: 14 | L25: {=SUMPRODUCT(('01_PCTN_DATA'!$A$4:$A$1000=IFERROR(INDEX(DM_DON_VI!$B$4:$B$185,MATCH(L$4,DM_DON_VI!$D$4:$D$185,0)),""))*IFERROR(INDEX('01_PCTN_DATA'!$A$4:$ZZ$1000,0,MATCH($G25,'01_PCTN_DATA'!$A$3:$ZZ$3,0)),0))} -> 0 | M25: {=SUMPRODUCT(('01_PCTN_DATA'!$A$4:$A$1000=IFERROR(INDEX(DM_DON_VI!$B$4:$B$185,MATCH(M$4,DM_DON_VI!$D$4:$D$185,0)),""))*IFERROR(INDEX('01_PCTN_DATA'!$A$4:$ZZ$1000,0,MATCH($G25,'01_PCTN_DATA'!$A$3:$ZZ$3,0)),0))} -> 0 | N25: {=SUMPRODUCT(('01_PCTN_DATA'!$A$4:$A$1000=IFERROR(INDEX(DM_DON_VI!$B$4:$B$185,MATCH(N$4,DM_DON_VI!$D$4:$D$185,0)),""))*IFERROR(INDEX('01_PCTN_DATA'!$A$4:$ZZ$1000,0,MATCH($G25,'01_PCTN_DATA'!$A$3:$ZZ$3,0)),0))} -> 0 | O25: {=SUMPRODUCT(('01_PCTN_DATA'!$A$4:$A$1000=IFERROR(INDEX(DM_DON_VI!$B$4:$B$185,MATCH(O$4,DM_DON_VI!$D$4:$D$185,0)),""))*IFERROR(INDEX('01_PCTN_DATA'!$A$4:$ZZ$1000,0,MATCH($G25,'01_PCTN_DATA'!$A$3:$ZZ$3,0)),0))} -> 0 | P25: {=SUMPRODUCT(('01_PCTN_DATA'!$A$4:$A$1000=IFERROR(INDEX(DM_DON_VI!$B$4:$B$185,MATCH(P$4,DM_DON_VI!$D$4:$D$185,0)),""))*IFERROR(INDEX('01_PCTN_DATA'!$A$4:$ZZ$1000,0,MATCH($G25,'01_PCTN_DATA'!$A$3:$ZZ$3,0)),0))} -> 0 | Q25: {=SUMPRODUCT(('01_PCTN_DATA'!$A$4:$A$1000=IFERROR(INDEX(DM_DON_VI!$B$4:$B$185,MATCH(Q$4,DM_DON_VI!$D$4:$D$185,0)),""))*IFERROR(INDEX('01_PCTN_DATA'!$A$4:$ZZ$1000,0,MATCH($G25,'01_PCTN_DATA'!$A$3:$ZZ$3,0)),0))} -> 0 | R25: {=SUMPRODUCT(('01_PCTN_DATA'!$A$4:$A$1000=IFERROR(INDEX(DM_DON_VI!$B$4:$B$185,MATCH(R$4,DM_DON_VI!$D$4:$D$185,0)),""))*IFERROR(INDEX('01_PCTN_DATA'!$A$4:$ZZ$1000,0,MATCH($G25,'01_PCTN_DATA'!$A$3:$ZZ$3,0)),0))} -> 0 | S25: {=SUMPRODUCT(('01_PCTN_DATA'!$A$4:$A$1000=IFERROR(INDEX(DM_DON_VI!$B$4:$B$185,MATCH(S$4,DM_DON_VI!$D$4:$D$185,0)),""))*IFERROR(INDEX('01_PCTN_DATA'!$A$4:$ZZ$1000,0,MATCH($G25,'01_PCTN_DATA'!$A$3:$ZZ$3,0)),0))} -> 0 | ... GK25: {=SUMPRODUCT(('01_PCTN_DATA'!$A$4:$A$1000=IFERROR(INDEX(DM_DON_VI!$B$4:$B$185,MATCH(GK$4,DM_DON_VI!$D$4:$D$185,0)),""))*IFERROR(INDEX('01_PCTN_DATA'!$A$4:$ZZ$1000,0,MATCH($G25,'01_PCTN_DATA'!$A$3:$ZZ$3,0)),0))} -> 0
A26: 15 | B26: 15 | C26: Số cơ quan, tổ chức, đơn vị bị phát hiện có vi phạm quy định về công khai, minh bạch về tổ chức và hoạt động | D26: CQ, TC, ĐV | E26: {=SUMPRODUCT(IFERROR(INDEX('01_PCTN_DATA'!$A$4:$ZZ$1000,0,MATCH($G26,'01_PCTN_DATA'!$A$3:$ZZ$3,0)),0))} -> 0 | G26: P01_15 | H26: ITEM | I26: PHÒNG NGỪA THAM NHŨNG TRONG CƠ QUAN, TỔ CHỨC, ĐƠN VỊ | J26: Kết quả thực hiện công khai, minh bạch về tổ chức và hoạt động | K26: 15 | L26: {=SUMPRODUCT(('01_PCTN_DATA'!$A$4:$A$1000=IFERROR(INDEX(DM_DON_VI!$B$4:$B$185,MATCH(L$4,DM_DON_VI!$D$4:$D$185,0)),""))*IFERROR(INDEX('01_PCTN_DATA'!$A$4:$ZZ$1000,0,MATCH($G26,'01_PCTN_DATA'!$A$3:$ZZ$3,0)),0))} -> 0 | M26: {=SUMPRODUCT(('01_PCTN_DATA'!$A$4:$A$1000=IFERROR(INDEX(DM_DON_VI!$B$4:$B$185,MATCH(M$4,DM_DON_VI!$D$4:$D$185,0)),""))*IFERROR(INDEX('01_PCTN_DATA'!$A$4:$ZZ$1000,0,MATCH($G26,'01_PCTN_DATA'!$A$3:$ZZ$3,0)),0))} -> 0 | N26: {=SUMPRODUCT(('01_PCTN_DATA'!$A$4:$A$1000=IFERROR(INDEX(DM_DON_VI!$B$4:$B$185,MATCH(N$4,DM_DON_VI!$D$4:$D$185,0)),""))*IFERROR(INDEX('01_PCTN_DATA'!$A$4:$ZZ$1000,0,MATCH($G26,'01_PCTN_DATA'!$A$3:$ZZ$3,0)),0))} -> 0 | O26: {=SUMPRODUCT(('01_PCTN_DATA'!$A$4:$A$1000=IFERROR(INDEX(DM_DON_VI!$B$4:$B$185,MATCH(O$4,DM_DON_VI!$D$4:$D$185,0)),""))*IFERROR(INDEX('01_PCTN_DATA'!$A$4:$ZZ$1000,0,MATCH($G26,'01_PCTN_DATA'!$A$3:$ZZ$3,0)),0))} -> 0 | P26: {=SUMPRODUCT(('01_PCTN_DATA'!$A$4:$A$1000=IFERROR(INDEX(DM_DON_VI!$B$4:$B$185,MATCH(P$4,DM_DON_VI!$D$4:$D$185,0)),""))*IFERROR(INDEX('01_PCTN_DATA'!$A$4:$ZZ$1000,0,MATCH($G26,'01_PCTN_DATA'!$A$3:$ZZ$3,0)),0))} -> 0 | Q26: {=SUMPRODUCT(('01_PCTN_DATA'!$A$4:$A$1000=IFERROR(INDEX(DM_DON_VI!$B$4:$B$185,MATCH(Q$4,DM_DON_VI!$D$4:$D$185,0)),""))*IFERROR(INDEX('01_PCTN_DATA'!$A$4:$ZZ$1000,0,MATCH($G26,'01_PCTN_DATA'!$A$3:$ZZ$3,0)),0))} -> 0 | R26: {=SUMPRODUCT(('01_PCTN_DATA'!$A$4:$A$1000=IFERROR(INDEX(DM_DON_VI!$B$4:$B$185,MATCH(R$4,DM_DON_VI!$D$4:$D$185,0)),""))*IFERROR(INDEX('01_PCTN_DATA'!$A$4:$ZZ$1000,0,MATCH($G26,'01_PCTN_DATA'!$A$3:$ZZ$3,0)),0))} -> 0 | S26: {=SUMPRODUCT(('01_PCTN_DATA'!$A$4:$A$1000=IFERROR(INDEX(DM_DON_VI!$B$4:$B$185,MATCH(S$4,DM_DON_VI!$D$4:$D$185,0)),""))*IFERROR(INDEX('01_PCTN_DATA'!$A$4:$ZZ$1000,0,MATCH($G26,'01_PCTN_DATA'!$A$3:$ZZ$3,0)),0))} -> 0 | ... GK26: {=SUMPRODUCT(('01_PCTN_DATA'!$A$4:$A$1000=IFERROR(INDEX(DM_DON_VI!$B$4:$B$185,MATCH(GK$4,DM_DON_VI!$D$4:$D$185,0)),""))*IFERROR(INDEX('01_PCTN_DATA'!$A$4:$ZZ$1000,0,MATCH($G26,'01_PCTN_DATA'!$A$3:$ZZ$3,0)),0))} -> 0
C27: Xây dựng và thực hiện định mức, tiêu chuẩn, chế độ | H27: SUBSECTION | I27: PHÒNG NGỪA THAM NHŨNG TRONG CƠ QUAN, TỔ CHỨC, ĐƠN VỊ | J27: Xây dựng và thực hiện định mức, tiêu chuẩn, chế độ
A28: 16 | B28: 16 | C28: Số văn bản về định mức, tiêu chuẩn, chế độ đã được ban hành mới | D28: Văn bản | E28: {=SUMPRODUCT(IFERROR(INDEX('01_PCTN_DATA'!$A$4:$ZZ$1000,0,MATCH($G28,'01_PCTN_DATA'!$A$3:$ZZ$3,0)),0))} -> 0 | G28: P01_16 | H28: ITEM | I28: PHÒNG NGỪA THAM NHŨNG TRONG CƠ QUAN, TỔ CHỨC, ĐƠN VỊ | J28: Xây dựng và thực hiện định mức, tiêu chuẩn, chế độ | K28: 16 | L28: {=SUMPRODUCT(('01_PCTN_DATA'!$A$4:$A$1000=IFERROR(INDEX(DM_DON_VI!$B$4:$B$185,MATCH(L$4,DM_DON_VI!$D$4:$D$185,0)),""))*IFERROR(INDEX('01_PCTN_DATA'!$A$4:$ZZ$1000,0,MATCH($G28,'01_PCTN_DATA'!$A$3:$ZZ$3,0)),0))} -> 0 | M28: {=SUMPRODUCT(('01_PCTN_DATA'!$A$4:$A$1000=IFERROR(INDEX(DM_DON_VI!$B$4:$B$185,MATCH(M$4,DM_DON_VI!$D$4:$D$185,0)),""))*IFERROR(INDEX('01_PCTN_DATA'!$A$4:$ZZ$1000,0,MATCH($G28,'01_PCTN_DATA'!$A$3:$ZZ$3,0)),0))} -> 0 | N28: {=SUMPRODUCT(('01_PCTN_DATA'!$A$4:$A$1000=IFERROR(INDEX(DM_DON_VI!$B$4:$B$185,MATCH(N$4,DM_DON_VI!$D$4:$D$185,0)),""))*IFERROR(INDEX('01_PCTN_DATA'!$A$4:$ZZ$1000,0,MATCH($G28,'01_PCTN_DATA'!$A$3:$ZZ$3,0)),0))} -> 0 | O28: {=SUMPRODUCT(('01_PCTN_DATA'!$A$4:$A$1000=IFERROR(INDEX(DM_DON_VI!$B$4:$B$185,MATCH(O$4,DM_DON_VI!$D$4:$D$185,0)),""))*IFERROR(INDEX('01_PCTN_DATA'!$A$4:$ZZ$1000,0,MATCH($G28,'01_PCTN_DATA'!$A$3:$ZZ$3,0)),0))} -> 0 | P28: {=SUMPRODUCT(('01_PCTN_DATA'!$A$4:$A$1000=IFERROR(INDEX(DM_DON_VI!$B$4:$B$185,MATCH(P$4,DM_DON_VI!$D$4:$D$185,0)),""))*IFERROR(INDEX('01_PCTN_DATA'!$A$4:$ZZ$1000,0,MATCH($G28,'01_PCTN_DATA'!$A$3:$ZZ$3,0)),0))} -> 0 | Q28: {=SUMPRODUCT(('01_PCTN_DATA'!$A$4:$A$1000=IFERROR(INDEX(DM_DON_VI!$B$4:$B$185,MATCH(Q$4,DM_DON_VI!$D$4:$D$185,0)),""))*IFERROR(INDEX('01_PCTN_DATA'!$A$4:$ZZ$1000,0,MATCH($G28,'01_PCTN_DATA'!$A$3:$ZZ$3,0)),0))} -> 0 | R28: {=SUMPRODUCT(('01_PCTN_DATA'!$A$4:$A$1000=IFERROR(INDEX(DM_DON_VI!$B$4:$B$185,MATCH(R$4,DM_DON_VI!$D$4:$D$185,0)),""))*IFERROR(INDEX('01_PCTN_DATA'!$A$4:$ZZ$1000,0,MATCH($G28,'01_PCTN_DATA'!$A$3:$ZZ$3,0)),0))} -> 0 | S28: {=SUMPRODUCT(('01_PCTN_DATA'!$A$4:$A$1000=IFERROR(INDEX(DM_DON_VI!$B$4:$B$185,MATCH(S$4,DM_DON_VI!$D$4:$D$185,0)),""))*IFERROR(INDEX('01_PCTN_DATA'!$A$4:$ZZ$1000,0,MATCH($G28,'01_PCTN_DATA'!$A$3:$ZZ$3,0)),0))} -> 0 | ... GK28: {=SUMPRODUCT(('01_PCTN_DATA'!$A$4:$A$1000=IFERROR(INDEX(DM_DON_VI!$B$4:$B$185,MATCH(GK$4,DM_DON_VI!$D$4:$D$185,0)),""))*IFERROR(INDEX('01_PCTN_DATA'!$A$4:$ZZ$1000,0,MATCH($G28,'01_PCTN_DATA'!$A$3:$ZZ$3,0)),0))} -> 0
A29: 17 | B29: 17 | C29: Số văn bản về định mức, tiêu chuẩn, chế độ đã được sửa đổi, bổ sung, bãi bỏ | D29: Văn bản | E29: {=SUMPRODUCT(IFERROR(INDEX('01_PCTN_DATA'!$A$4:$ZZ$1000,0,MATCH($G29,'01_PCTN_DATA'!$A$3:$ZZ$3,0)),0))} -> 0 | G29: P01_17 | H29: ITEM | I29: PHÒNG NGỪA THAM NHŨNG TRONG CƠ QUAN, TỔ CHỨC, ĐƠN VỊ | J29: Xây dựng và thực hiện định mức, tiêu chuẩn, chế độ | K29: 17 | L29: {=SUMPRODUCT(('01_PCTN_DATA'!$A$4:$A$1000=IFERROR(INDEX(DM_DON_VI!$B$4:$B$185,MATCH(L$4,DM_DON_VI!$D$4:$D$185,0)),""))*IFERROR(INDEX('01_PCTN_DATA'!$A$4:$ZZ$1000,0,MATCH($G29,'01_PCTN_DATA'!$A$3:$ZZ$3,0)),0))} -> 0 | M29: {=SUMPRODUCT(('01_PCTN_DATA'!$A$4:$A$1000=IFERROR(INDEX(DM_DON_VI!$B$4:$B$185,MATCH(M$4,DM_DON_VI!$D$4:$D$185,0)),""))*IFERROR(INDEX('01_PCTN_DATA'!$A$4:$ZZ$1000,0,MATCH($G29,'01_PCTN_DATA'!$A$3:$ZZ$3,0)),0))} -> 0 | N29: {=SUMPRODUCT(('01_PCTN_DATA'!$A$4:$A$1000=IFERROR(INDEX(DM_DON_VI!$B$4:$B$185,MATCH(N$4,DM_DON_VI!$D$4:$D$185,0)),""))*IFERROR(INDEX('01_PCTN_DATA'!$A$4:$ZZ$1000,0,MATCH($G29,'01_PCTN_DATA'!$A$3:$ZZ$3,0)),0))} -> 0 | O29: {=SUMPRODUCT(('01_PCTN_DATA'!$A$4:$A$1000=IFERROR(INDEX(DM_DON_VI!$B$4:$B$185,MATCH(O$4,DM_DON_VI!$D$4:$D$185,0)),""))*IFERROR(INDEX('01_PCTN_DATA'!$A$4:$ZZ$1000,0,MATCH($G29,'01_PCTN_DATA'!$A$3:$ZZ$3,0)),0))} -> 0 | P29: {=SUMPRODUCT(('01_PCTN_DATA'!$A$4:$A$1000=IFERROR(INDEX(DM_DON_VI!$B$4:$B$185,MATCH(P$4,DM_DON_VI!$D$4:$D$185,0)),""))*IFERROR(INDEX('01_PCTN_DATA'!$A$4:$ZZ$1000,0,MATCH($G29,'01_PCTN_DATA'!$A$3:$ZZ$3,0)),0))} -> 0 | Q29: {=SUMPRODUCT(('01_PCTN_DATA'!$A$4:$A$1000=IFERROR(INDEX(DM_DON_VI!$B$4:$B$185,MATCH(Q$4,DM_DON_VI!$D$4:$D$185,0)),""))*IFERROR(INDEX('01_PCTN_DATA'!$A$4:$ZZ$1000,0,MATCH($G29,'01_PCTN_DATA'!$A$3:$ZZ$3,0)),0))} -> 0 | R29: {=SUMPRODUCT(('01_PCTN_DATA'!$A$4:$A$1000=IFERROR(INDEX(DM_DON_VI!$B$4:$B$185,MATCH(R$4,DM_DON_VI!$D$4:$D$185,0)),""))*IFERROR(INDEX('01_PCTN_DATA'!$A$4:$ZZ$1000,0,MATCH($G29,'01_PCTN_DATA'!$A$3:$ZZ$3,0)),0))} -> 0 | S29: {=SUMPRODUCT(('01_PCTN_DATA'!$A$4:$A$1000=IFERROR(INDEX(DM_DON_VI!$B$4:$B$185,MATCH(S$4,DM_DON_VI!$D$4:$D$185,0)),""))*IFERROR(INDEX('01_PCTN_DATA'!$A$4:$ZZ$1000,0,MATCH($G29,'01_PCTN_DATA'!$A$3:$ZZ$3,0)),0))} -> 0 | ... GK29: {=SUMPRODUCT(('01_PCTN_DATA'!$A$4:$A$1000=IFERROR(INDEX(DM_DON_VI!$B$4:$B$185,MATCH(GK$4,DM_DON_VI!$D$4:$D$185,0)),""))*IFERROR(INDEX('01_PCTN_DATA'!$A$4:$ZZ$1000,0,MATCH($G29,'01_PCTN_DATA'!$A$3:$ZZ$3,0)),0))} -> 0
A30: 18 | B30: 18 | C30: Số cuộc thanh tra, kiểm tra việc thực hiện các quy định về định mức, tiêu chuẩn, chế độ | D30: Cuộc | E30: {=SUMPRODUCT(IFERROR(INDEX('01_PCTN_DATA'!$A$4:$ZZ$1000,0,MATCH($G30,'01_PCTN_DATA'!$A$3:$ZZ$3,0)),0))} -> 0 | G30: P01_18 | H30: ITEM | I30: PHÒNG NGỪA THAM NHŨNG TRONG CƠ QUAN, TỔ CHỨC, ĐƠN VỊ | J30: Xây dựng và thực hiện định mức, tiêu chuẩn, chế độ | K30: 18 | L30: {=SUMPRODUCT(('01_PCTN_DATA'!$A$4:$A$1000=IFERROR(INDEX(DM_DON_VI!$B$4:$B$185,MATCH(L$4,DM_DON_VI!$D$4:$D$185,0)),""))*IFERROR(INDEX('01_PCTN_DATA'!$A$4:$ZZ$1000,0,MATCH($G30,'01_PCTN_DATA'!$A$3:$ZZ$3,0)),0))} -> 0 | M30: {=SUMPRODUCT(('01_PCTN_DATA'!$A$4:$A$1000=IFERROR(INDEX(DM_DON_VI!$B$4:$B$185,MATCH(M$4,DM_DON_VI!$D$4:$D$185,0)),""))*IFERROR(INDEX('01_PCTN_DATA'!$A$4:$ZZ$1000,0,MATCH($G30,'01_PCTN_DATA'!$A$3:$ZZ$3,0)),0))} -> 0 | N30: {=SUMPRODUCT(('01_PCTN_DATA'!$A$4:$A$1000=IFERROR(INDEX(DM_DON_VI!$B$4:$B$185,MATCH(N$4,DM_DON_VI!$D$4:$D$185,0)),""))*IFERROR(INDEX('01_PCTN_DATA'!$A$4:$ZZ$1000,0,MATCH($G30,'01_PCTN_DATA'!$A$3:$ZZ$3,0)),0))} -> 0 | O30: {=SUMPRODUCT(('01_PCTN_DATA'!$A$4:$A$1000=IFERROR(INDEX(DM_DON_VI!$B$4:$B$185,MATCH(O$4,DM_DON_VI!$D$4:$D$185,0)),""))*IFERROR(INDEX('01_PCTN_DATA'!$A$4:$ZZ$1000,0,MATCH($G30,'01_PCTN_DATA'!$A$3:$ZZ$3,0)),0))} -> 0 | P30: {=SUMPRODUCT(('01_PCTN_DATA'!$A$4:$A$1000=IFERROR(INDEX(DM_DON_VI!$B$4:$B$185,MATCH(P$4,DM_DON_VI!$D$4:$D$185,0)),""))*IFERROR(INDEX('01_PCTN_DATA'!$A$4:$ZZ$1000,0,MATCH($G30,'01_PCTN_DATA'!$A$3:$ZZ$3,0)),0))} -> 0 | Q30: {=SUMPRODUCT(('01_PCTN_DATA'!$A$4:$A$1000=IFERROR(INDEX(DM_DON_VI!$B$4:$B$185,MATCH(Q$4,DM_DON_VI!$D$4:$D$185,0)),""))*IFERROR(INDEX('01_PCTN_DATA'!$A$4:$ZZ$1000,0,MATCH($G30,'01_PCTN_DATA'!$A$3:$ZZ$3,0)),0))} -> 0 | R30: {=SUMPRODUCT(('01_PCTN_DATA'!$A$4:$A$1000=IFERROR(INDEX(DM_DON_VI!$B$4:$B$185,MATCH(R$4,DM_DON_VI!$D$4:$D$185,0)),""))*IFERROR(INDEX('01_PCTN_DATA'!$A$4:$ZZ$1000,0,MATCH($G30,'01_PCTN_DATA'!$A$3:$ZZ$3,0)),0))} -> 0 | S30: {=SUMPRODUCT(('01_PCTN_DATA'!$A$4:$A$1000=IFERROR(INDEX(DM_DON_VI!$B$4:$B$185,MATCH(S$4,DM_DON_VI!$D$4:$D$185,0)),""))*IFERROR(INDEX('01_PCTN_DATA'!$A$4:$ZZ$1000,0,MATCH($G30,'01_PCTN_DATA'!$A$3:$ZZ$3,0)),0))} -> 0 | ... GK30: {=SUMPRODUCT(('01_PCTN_DATA'!$A$4:$A$1000=IFERROR(INDEX(DM_DON_VI!$B$4:$B$185,MATCH(GK$4,DM_DON_VI!$D$4:$D$185,0)),""))*IFERROR(INDEX('01_PCTN_DATA'!$A$4:$ZZ$1000,0,MATCH($G30,'01_PCTN_DATA'!$A$3:$ZZ$3,0)),0))} -> 0
A31: 19 | B31: 19 | C31: Số vụ vi phạm các quy định về định mức, tiêu chuẩn, chế độ | D31: Vụ | E31: {=SUMPRODUCT(IFERROR(INDEX('01_PCTN_DATA'!$A$4:$ZZ$1000,0,MATCH($G31,'01_PCTN_DATA'!$A$3:$ZZ$3,0)),0))} -> 0 | G31: P01_19 | H31: ITEM | I31: PHÒNG NGỪA THAM NHŨNG TRONG CƠ QUAN, TỔ CHỨC, ĐƠN VỊ | J31: Xây dựng và thực hiện định mức, tiêu chuẩn, chế độ | K31: 19 | L31: {=SUMPRODUCT(('01_PCTN_DATA'!$A$4:$A$1000=IFERROR(INDEX(DM_DON_VI!$B$4:$B$185,MATCH(L$4,DM_DON_VI!$D$4:$D$185,0)),""))*IFERROR(INDEX('01_PCTN_DATA'!$A$4:$ZZ$1000,0,MATCH($G31,'01_PCTN_DATA'!$A$3:$ZZ$3,0)),0))} -> 0 | M31: {=SUMPRODUCT(('01_PCTN_DATA'!$A$4:$A$1000=IFERROR(INDEX(DM_DON_VI!$B$4:$B$185,MATCH(M$4,DM_DON_VI!$D$4:$D$185,0)),""))*IFERROR(INDEX('01_PCTN_DATA'!$A$4:$ZZ$1000,0,MATCH($G31,'01_PCTN_DATA'!$A$3:$ZZ$3,0)),0))} -> 0 | N31: {=SUMPRODUCT(('01_PCTN_DATA'!$A$4:$A$1000=IFERROR(INDEX(DM_DON_VI!$B$4:$B$185,MATCH(N$4,DM_DON_VI!$D$4:$D$185,0)),""))*IFERROR(INDEX('01_PCTN_DATA'!$A$4:$ZZ$1000,0,MATCH($G31,'01_PCTN_DATA'!$A$3:$ZZ$3,0)),0))} -> 0 | O31: {=SUMPRODUCT(('01_PCTN_DATA'!$A$4:$A$1000=IFERROR(INDEX(DM_DON_VI!$B$4:$B$185,MATCH(O$4,DM_DON_VI!$D$4:$D$185,0)),""))*IFERROR(INDEX('01_PCTN_DATA'!$A$4:$ZZ$1000,0,MATCH($G31,'01_PCTN_DATA'!$A$3:$ZZ$3,0)),0))} -> 0 | P31: {=SUMPRODUCT(('01_PCTN_DATA'!$A$4:$A$1000=IFERROR(INDEX(DM_DON_VI!$B$4:$B$185,MATCH(P$4,DM_DON_VI!$D$4:$D$185,0)),""))*IFERROR(INDEX('01_PCTN_DATA'!$A$4:$ZZ$1000,0,MATCH($G31,'01_PCTN_DATA'!$A$3:$ZZ$3,0)),0))} -> 0 | Q31: {=SUMPRODUCT(('01_PCTN_DATA'!$A$4:$A$1000=IFERROR(INDEX(DM_DON_VI!$B$4:$B$185,MATCH(Q$4,DM_DON_VI!$D$4:$D$185,0)),""))*IFERROR(INDEX('01_PCTN_DATA'!$A$4:$ZZ$1000,0,MATCH($G31,'01_PCTN_DATA'!$A$3:$ZZ$3,0)),0))} -> 0 | R31: {=SUMPRODUCT(('01_PCTN_DATA'!$A$4:$A$1000=IFERROR(INDEX(DM_DON_VI!$B$4:$B$185,MATCH(R$4,DM_DON_VI!$D$4:$D$185,0)),""))*IFERROR(INDEX('01_PCTN_DATA'!$A$4:$ZZ$1000,0,MATCH($G31,'01_PCTN_DATA'!$A$3:$ZZ$3,0)),0))} -> 0 | S31: {=SUMPRODUCT(('01_PCTN_DATA'!$A$4:$A$1000=IFERROR(INDEX(DM_DON_VI!$B$4:$B$185,MATCH(S$4,DM_DON_VI!$D$4:$D$185,0)),""))*IFERROR(INDEX('01_PCTN_DATA'!$A$4:$ZZ$1000,0,MATCH($G31,'01_PCTN_DATA'!$A$3:$ZZ$3,0)),0))} -> 0 | ... GK31: {=SUMPRODUCT(('01_PCTN_DATA'!$A$4:$A$1000=IFERROR(INDEX(DM_DON_VI!$B$4:$B$185,MATCH(GK$4,DM_DON_VI!$D$4:$D$185,0)),""))*IFERROR(INDEX('01_PCTN_DATA'!$A$4:$ZZ$1000,0,MATCH($G31,'01_PCTN_DATA'!$A$3:$ZZ$3,0)),0))} -> 0
A32: 20 | B32: 20 | C32: Số người vi phạm các quy định về định mức, tiêu chuẩn, chế độ | D32: Người | E32: {=SUMPRODUCT(IFERROR(INDEX('01_PCTN_DATA'!$A$4:$ZZ$1000,0,MATCH($G32,'01_PCTN_DATA'!$A$3:$ZZ$3,0)),0))} -> 0 | G32: P01_20 | H32: ITEM | I32: PHÒNG NGỪA THAM NHŨNG TRONG CƠ QUAN, TỔ CHỨC, ĐƠN VỊ | J32: Xây dựng và thực hiện định mức, tiêu chuẩn, chế độ | K32: 20 | L32: {=SUMPRODUCT(('01_PCTN_DATA'!$A$4:$A$1000=IFERROR(INDEX(DM_DON_VI!$B$4:$B$185,MATCH(L$4,DM_DON_VI!$D$4:$D$185,0)),""))*IFERROR(INDEX('01_PCTN_DATA'!$A$4:$ZZ$1000,0,MATCH($G32,'01_PCTN_DATA'!$A$3:$ZZ$3,0)),0))} -> 0 | M32: {=SUMPRODUCT(('01_PCTN_DATA'!$A$4:$A$1000=IFERROR(INDEX(DM_DON_VI!$B$4:$B$185,MATCH(M$4,DM_DON_VI!$D$4:$D$185,0)),""))*IFERROR(INDEX('01_PCTN_DATA'!$A$4:$ZZ$1000,0,MATCH($G32,'01_PCTN_DATA'!$A$3:$ZZ$3,0)),0))} -> 0 | N32: {=SUMPRODUCT(('01_PCTN_DATA'!$A$4:$A$1000=IFERROR(INDEX(DM_DON_VI!$B$4:$B$185,MATCH(N$4,DM_DON_VI!$D$4:$D$185,0)),""))*IFERROR(INDEX('01_PCTN_DATA'!$A$4:$ZZ$1000,0,MATCH($G32,'01_PCTN_DATA'!$A$3:$ZZ$3,0)),0))} -> 0 | O32: {=SUMPRODUCT(('01_PCTN_DATA'!$A$4:$A$1000=IFERROR(INDEX(DM_DON_VI!$B$4:$B$185,MATCH(O$4,DM_DON_VI!$D$4:$D$185,0)),""))*IFERROR(INDEX('01_PCTN_DATA'!$A$4:$ZZ$1000,0,MATCH($G32,'01_PCTN_DATA'!$A$3:$ZZ$3,0)),0))} -> 0 | P32: {=SUMPRODUCT(('01_PCTN_DATA'!$A$4:$A$1000=IFERROR(INDEX(DM_DON_VI!$B$4:$B$185,MATCH(P$4,DM_DON_VI!$D$4:$D$185,0)),""))*IFERROR(INDEX('01_PCTN_DATA'!$A$4:$ZZ$1000,0,MATCH($G32,'01_PCTN_DATA'!$A$3:$ZZ$3,0)),0))} -> 0 | Q32: {=SUMPRODUCT(('01_PCTN_DATA'!$A$4:$A$1000=IFERROR(INDEX(DM_DON_VI!$B$4:$B$185,MATCH(Q$4,DM_DON_VI!$D$4:$D$185,0)),""))*IFERROR(INDEX('01_PCTN_DATA'!$A$4:$ZZ$1000,0,MATCH($G32,'01_PCTN_DATA'!$A$3:$ZZ$3,0)),0))} -> 0 | R32: {=SUMPRODUCT(('01_PCTN_DATA'!$A$4:$A$1000=IFERROR(INDEX(DM_DON_VI!$B$4:$B$185,MATCH(R$4,DM_DON_VI!$D$4:$D$185,0)),""))*IFERROR(INDEX('01_PCTN_DATA'!$A$4:$ZZ$1000,0,MATCH($G32,'01_PCTN_DATA'!$A$3:$ZZ$3,0)),0))} -> 0 | S32: {=SUMPRODUCT(('01_PCTN_DATA'!$A$4:$A$1000=IFERROR(INDEX(DM_DON_VI!$B$4:$B$185,MATCH(S$4,DM_DON_VI!$D$4:$D$185,0)),""))*IFERROR(INDEX('01_PCTN_DATA'!$A$4:$ZZ$1000,0,MATCH($G32,'01_PCTN_DATA'!$A$3:$ZZ$3,0)),0))} -> 0 | ... GK32: {=SUMPRODUCT(('01_PCTN_DATA'!$A$4:$A$1000=IFERROR(INDEX(DM_DON_VI!$B$4:$B$185,MATCH(GK$4,DM_DON_VI!$D$4:$D$185,0)),""))*IFERROR(INDEX('01_PCTN_DATA'!$A$4:$ZZ$1000,0,MATCH($G32,'01_PCTN_DATA'!$A$3:$ZZ$3,0)),0))} -> 0
A33: 21 | B33: 21 | C33: Số người vi phạm các quy định về định mức, tiêu chuẩn, chế độ đã bị xử lý hành chính | D33: Người | E33: {=SUMPRODUCT(IFERROR(INDEX('01_PCTN_DATA'!$A$4:$ZZ$1000,0,MATCH($G33,'01_PCTN_DATA'!$A$3:$ZZ$3,0)),0))} -> 0 | G33: P01_21 | H33: ITEM | I33: PHÒNG NGỪA THAM NHŨNG TRONG CƠ QUAN, TỔ CHỨC, ĐƠN VỊ | J33: Xây dựng và thực hiện định mức, tiêu chuẩn, chế độ | K33: 21 | L33: {=SUMPRODUCT(('01_PCTN_DATA'!$A$4:$A$1000=IFERROR(INDEX(DM_DON_VI!$B$4:$B$185,MATCH(L$4,DM_DON_VI!$D$4:$D$185,0)),""))*IFERROR(INDEX('01_PCTN_DATA'!$A$4:$ZZ$1000,0,MATCH($G33,'01_PCTN_DATA'!$A$3:$ZZ$3,0)),0))} -> 0 | M33: {=SUMPRODUCT(('01_PCTN_DATA'!$A$4:$A$1000=IFERROR(INDEX(DM_DON_VI!$B$4:$B$185,MATCH(M$4,DM_DON_VI!$D$4:$D$185,0)),""))*IFERROR(INDEX('01_PCTN_DATA'!$A$4:$ZZ$1000,0,MATCH($G33,'01_PCTN_DATA'!$A$3:$ZZ$3,0)),0))} -> 0 | N33: {=SUMPRODUCT(('01_PCTN_DATA'!$A$4:$A$1000=IFERROR(INDEX(DM_DON_VI!$B$4:$B$185,MATCH(N$4,DM_DON_VI!$D$4:$D$185,0)),""))*IFERROR(INDEX('01_PCTN_DATA'!$A$4:$ZZ$1000,0,MATCH($G33,'01_PCTN_DATA'!$A$3:$ZZ$3,0)),0))} -> 0 | O33: {=SUMPRODUCT(('01_PCTN_DATA'!$A$4:$A$1000=IFERROR(INDEX(DM_DON_VI!$B$4:$B$185,MATCH(O$4,DM_DON_VI!$D$4:$D$185,0)),""))*IFERROR(INDEX('01_PCTN_DATA'!$A$4:$ZZ$1000,0,MATCH($G33,'01_PCTN_DATA'!$A$3:$ZZ$3,0)),0))} -> 0 | P33: {=SUMPRODUCT(('01_PCTN_DATA'!$A$4:$A$1000=IFERROR(INDEX(DM_DON_VI!$B$4:$B$185,MATCH(P$4,DM_DON_VI!$D$4:$D$185,0)),""))*IFERROR(INDEX('01_PCTN_DATA'!$A$4:$ZZ$1000,0,MATCH($G33,'01_PCTN_DATA'!$A$3:$ZZ$3,0)),0))} -> 0 | Q33: {=SUMPRODUCT(('01_PCTN_DATA'!$A$4:$A$1000=IFERROR(INDEX(DM_DON_VI!$B$4:$B$185,MATCH(Q$4,DM_DON_VI!$D$4:$D$185,0)),""))*IFERROR(INDEX('01_PCTN_DATA'!$A$4:$ZZ$1000,0,MATCH($G33,'01_PCTN_DATA'!$A$3:$ZZ$3,0)),0))} -> 0 | R33: {=SUMPRODUCT(('01_PCTN_DATA'!$A$4:$A$1000=IFERROR(INDEX(DM_DON_VI!$B$4:$B$185,MATCH(R$4,DM_DON_VI!$D$4:$D$185,0)),""))*IFERROR(INDEX('01_PCTN_DATA'!$A$4:$ZZ$1000,0,MATCH($G33,'01_PCTN_DATA'!$A$3:$ZZ$3,0)),0))} -> 0 | S33: {=SUMPRODUCT(('01_PCTN_DATA'!$A$4:$A$1000=IFERROR(INDEX(DM_DON_VI!$B$4:$B$185,MATCH(S$4,DM_DON_VI!$D$4:$D$185,0)),""))*IFERROR(INDEX('01_PCTN_DATA'!$A$4:$ZZ$1000,0,MATCH($G33,'01_PCTN_DATA'!$A$3:$ZZ$3,0)),0))} -> 0 | ... GK33: {=SUMPRODUCT(('01_PCTN_DATA'!$A$4:$A$1000=IFERROR(INDEX(DM_DON_VI!$B$4:$B$185,MATCH(GK$4,DM_DON_VI!$D$4:$D$185,0)),""))*IFERROR(INDEX('01_PCTN_DATA'!$A$4:$ZZ$1000,0,MATCH($G33,'01_PCTN_DATA'!$A$3:$ZZ$3,0)),0))} -> 0
A34: 22 | B34: 22 | C34: Số người vi phạm các quy định về định mức, tiêu chuẩn, chế độ đã bị xử lý hình sự | D34: Người | E34: {=SUMPRODUCT(IFERROR(INDEX('01_PCTN_DATA'!$A$4:$ZZ$1000,0,MATCH($G34,'01_PCTN_DATA'!$A$3:$ZZ$3,0)),0))} -> 0 | G34: P01_22 | H34: ITEM | I34: PHÒNG NGỪA THAM NHŨNG TRONG CƠ QUAN, TỔ CHỨC, ĐƠN VỊ | J34: Xây dựng và thực hiện định mức, tiêu chuẩn, chế độ | K34: 22 | L34: {=SUMPRODUCT(('01_PCTN_DATA'!$A$4:$A$1000=IFERROR(INDEX(DM_DON_VI!$B$4:$B$185,MATCH(L$4,DM_DON_VI!$D$4:$D$185,0)),""))*IFERROR(INDEX('01_PCTN_DATA'!$A$4:$ZZ$1000,0,MATCH($G34,'01_PCTN_DATA'!$A$3:$ZZ$3,0)),0))} -> 0 | M34: {=SUMPRODUCT(('01_PCTN_DATA'!$A$4:$A$1000=IFERROR(INDEX(DM_DON_VI!$B$4:$B$185,MATCH(M$4,DM_DON_VI!$D$4:$D$185,0)),""))*IFERROR(INDEX('01_PCTN_DATA'!$A$4:$ZZ$1000,0,MATCH($G34,'01_PCTN_DATA'!$A$3:$ZZ$3,0)),0))} -> 0 | N34: {=SUMPRODUCT(('01_PCTN_DATA'!$A$4:$A$1000=IFERROR(INDEX(DM_DON_VI!$B$4:$B$185,MATCH(N$4,DM_DON_VI!$D$4:$D$185,0)),""))*IFERROR(INDEX('01_PCTN_DATA'!$A$4:$ZZ$1000,0,MATCH($G34,'01_PCTN_DATA'!$A$3:$ZZ$3,0)),0))} -> 0 | O34: {=SUMPRODUCT(('01_PCTN_DATA'!$A$4:$A$1000=IFERROR(INDEX(DM_DON_VI!$B$4:$B$185,MATCH(O$4,DM_DON_VI!$D$4:$D$185,0)),""))*IFERROR(INDEX('01_PCTN_DATA'!$A$4:$ZZ$1000,0,MATCH($G34,'01_PCTN_DATA'!$A$3:$ZZ$3,0)),0))} -> 0 | P34: {=SUMPRODUCT(('01_PCTN_DATA'!$A$4:$A$1000=IFERROR(INDEX(DM_DON_VI!$B$4:$B$185,MATCH(P$4,DM_DON_VI!$D$4:$D$185,0)),""))*IFERROR(INDEX('01_PCTN_DATA'!$A$4:$ZZ$1000,0,MATCH($G34,'01_PCTN_DATA'!$A$3:$ZZ$3,0)),0))} -> 0 | Q34: {=SUMPRODUCT(('01_PCTN_DATA'!$A$4:$A$1000=IFERROR(INDEX(DM_DON_VI!$B$4:$B$185,MATCH(Q$4,DM_DON_VI!$D$4:$D$185,0)),""))*IFERROR(INDEX('01_PCTN_DATA'!$A$4:$ZZ$1000,0,MATCH($G34,'01_PCTN_DATA'!$A$3:$ZZ$3,0)),0))} -> 0 | R34: {=SUMPRODUCT(('01_PCTN_DATA'!$A$4:$A$1000=IFERROR(INDEX(DM_DON_VI!$B$4:$B$185,MATCH(R$4,DM_DON_VI!$D$4:$D$185,0)),""))*IFERROR(INDEX('01_PCTN_DATA'!$A$4:$ZZ$1000,0,MATCH($G34,'01_PCTN_DATA'!$A$3:$ZZ$3,0)),0))} -> 0 | S34: {=SUMPRODUCT(('01_PCTN_DATA'!$A$4:$A$1000=IFERROR(INDEX(DM_DON_VI!$B$4:$B$185,MATCH(S$4,DM_DON_VI!$D$4:$D$185,0)),""))*IFERROR(INDEX('01_PCTN_DATA'!$A$4:$ZZ$1000,0,MATCH($G34,'01_PCTN_DATA'!$A$3:$ZZ$3,0)),0))} -> 0 | ... GK34: {=SUMPRODUCT(('01_PCTN_DATA'!$A$4:$A$1000=IFERROR(INDEX(DM_DON_VI!$B$4:$B$185,MATCH(GK$4,DM_DON_VI!$D$4:$D$185,0)),""))*IFERROR(INDEX('01_PCTN_DATA'!$A$4:$ZZ$1000,0,MATCH($G34,'01_PCTN_DATA'!$A$3:$ZZ$3,0)),0))} -> 0
A35: 23 | B35: 23 | C35: Tổng giá trị các vi phạm về định mức, tiêu chuẩn, chế độ được kiến nghị thu hồi và bồi thường (tiền Việt Nam + ngoại tệ, tài sản khác được quy đổi ra tiền Việt Nam) | D35: Triệu đồng | E35: {=SUMPRODUCT(IFERROR(INDEX('01_PCTN_DATA'!$A$4:$ZZ$1000,0,MATCH($G35,'01_PCTN_DATA'!$A$3:$ZZ$3,0)),0))} -> 0 | G35: P01_23 | H35: ITEM | I35: PHÒNG NGỪA THAM NHŨNG TRONG CƠ QUAN, TỔ CHỨC, ĐƠN VỊ | J35: Xây dựng và thực hiện định mức, tiêu chuẩn, chế độ | K35: 23 | L35: {=SUMPRODUCT(('01_PCTN_DATA'!$A$4:$A$1000=IFERROR(INDEX(DM_DON_VI!$B$4:$B$185,MATCH(L$4,DM_DON_VI!$D$4:$D$185,0)),""))*IFERROR(INDEX('01_PCTN_DATA'!$A$4:$ZZ$1000,0,MATCH($G35,'01_PCTN_DATA'!$A$3:$ZZ$3,0)),0))} -> 0 | M35: {=SUMPRODUCT(('01_PCTN_DATA'!$A$4:$A$1000=IFERROR(INDEX(DM_DON_VI!$B$4:$B$185,MATCH(M$4,DM_DON_VI!$D$4:$D$185,0)),""))*IFERROR(INDEX('01_PCTN_DATA'!$A$4:$ZZ$1000,0,MATCH($G35,'01_PCTN_DATA'!$A$3:$ZZ$3,0)),0))} -> 0 | N35: {=SUMPRODUCT(('01_PCTN_DATA'!$A$4:$A$1000=IFERROR(INDEX(DM_DON_VI!$B$4:$B$185,MATCH(N$4,DM_DON_VI!$D$4:$D$185,0)),""))*IFERROR(INDEX('01_PCTN_DATA'!$A$4:$ZZ$1000,0,MATCH($G35,'01_PCTN_DATA'!$A$3:$ZZ$3,0)),0))} -> 0 | O35: {=SUMPRODUCT(('01_PCTN_DATA'!$A$4:$A$1000=IFERROR(INDEX(DM_DON_VI!$B$4:$B$185,MATCH(O$4,DM_DON_VI!$D$4:$D$185,0)),""))*IFERROR(INDEX('01_PCTN_DATA'!$A$4:$ZZ$1000,0,MATCH($G35,'01_PCTN_DATA'!$A$3:$ZZ$3,0)),0))} -> 0 | P35: {=SUMPRODUCT(('01_PCTN_DATA'!$A$4:$A$1000=IFERROR(INDEX(DM_DON_VI!$B$4:$B$185,MATCH(P$4,DM_DON_VI!$D$4:$D$185,0)),""))*IFERROR(INDEX('01_PCTN_DATA'!$A$4:$ZZ$1000,0,MATCH($G35,'01_PCTN_DATA'!$A$3:$ZZ$3,0)),0))} -> 0 | Q35: {=SUMPRODUCT(('01_PCTN_DATA'!$A$4:$A$1000=IFERROR(INDEX(DM_DON_VI!$B$4:$B$185,MATCH(Q$4,DM_DON_VI!$D$4:$D$185,0)),""))*IFERROR(INDEX('01_PCTN_DATA'!$A$4:$ZZ$1000,0,MATCH($G35,'01_PCTN_DATA'!$A$3:$ZZ$3,0)),0))} -> 0 | R35: {=SUMPRODUCT(('01_PCTN_DATA'!$A$4:$A$1000=IFERROR(INDEX(DM_DON_VI!$B$4:$B$185,MATCH(R$4,DM_DON_VI!$D$4:$D$185,0)),""))*IFERROR(INDEX('01_PCTN_DATA'!$A$4:$ZZ$1000,0,MATCH($G35,'01_PCTN_DATA'!$A$3:$ZZ$3,0)),0))} -> 0 | S35: {=SUMPRODUCT(('01_PCTN_DATA'!$A$4:$A$1000=IFERROR(INDEX(DM_DON_VI!$B$4:$B$185,MATCH(S$4,DM_DON_VI!$D$4:$D$185,0)),""))*IFERROR(INDEX('01_PCTN_DATA'!$A$4:$ZZ$1000,0,MATCH($G35,'01_PCTN_DATA'!$A$3:$ZZ$3,0)),0))} -> 0 | ... GK35: {=SUMPRODUCT(('01_PCTN_DATA'!$A$4:$A$1000=IFERROR(INDEX(DM_DON_VI!$B$4:$B$185,MATCH(GK$4,DM_DON_VI!$D$4:$D$185,0)),""))*IFERROR(INDEX('01_PCTN_DATA'!$A$4:$ZZ$1000,0,MATCH($G35,'01_PCTN_DATA'!$A$3:$ZZ$3,0)),0))} -> 0
